Workbook

Sheet DEPARTMENTS
A1: ID | B1: NAME | C1: B/F | D1: COLLECTIONS | E1: EXP | F1: BAL | H1: JAN | I1: FEB | J1: MAR | K1: APR | L1: MAY | M1: JUN | N1: JUL | O1: AUG | P1: SEP | Q1: OCT | R1: NOV | S1: DEC | T1: TOTAL
B2: SABBATH SCHOOL | C2: 0 | D2: =SUMIF(COLLECTION!D:D,DEPARTMENTS!B:B,COLLECTION!E:E)+SUMIF(BANK!D:D,DEPARTMENTS!B:B,BANK!E:E)+SUMIF(TRUST!D:D,DEPARTMENTS!B:B,TRUST!E:E) -> 49940 | H2: =SUMIFS(COLLECTION!$E:$E, COLLECTION!$D:$D,DEPARTMENTS!$B:$B, COLLECTION!$B:$B, H$13, COLLECTION!$B:$B, H$13) + SUMIFS(BANK!$E:$E, BANK!$D:$D,DEPARTMENTS!$B:$B, BANK!$B:$B, H$13, BANK!$B:$B, H$13) + SUMIFS(TRUST!$E:$E, TRUST!$D:$D,DEPARTMENTS!$B:$B, TRUST!$B:$B, H$13, TRUST!$B:$B, H$13) -> 12095 | I2: =SUMIFS(COLLECTION!$E:$E, COLLECTION!$D:$D,DEPARTMENTS!$B:$B, COLLECTION!$B:$B, I$13, COLLECTION!$B:$B, I$13) + SUMIFS(BANK!$E:$E, BANK!$D:$D,DEPARTMENTS!$B:$B, BANK!$B:$B, I$13, BANK!$B:$B, I$13) + SUMIFS(TRUST!$E:$E, TRUST!$D:$D,DEPARTMENTS!$B:$B, TRUST!$B:$B, I$13, TRUST!$B:$B, I$13) -> 8435 | J2: =SUMIFS(COLLECTION!$E:$E, COLLECTION!$D:$D,DEPARTMENTS!$B:$B, COLLECTION!$B:$B, J$13, COLLECTION!$B:$B, J$13) + SUMIFS(BANK!$E:$E, BANK!$D:$D,DEPARTMENTS!$B:$B, BANK!$B:$B, J$13, BANK!$B:$B, J$13) + SUMIFS(TRUST!$E:$E, TRUST!$D:$D,DEPARTMENTS!$B:$B, TRUST!$B:$B, J$13, TRUST!$B:$B, J$13) -> 7665 | K2: =SUMIFS(COLLECTION!$E:$E, COLLECTION!$D:$D,DEPARTMENTS!$B:$B, COLLECTION!$B:$B, K$13, COLLECTION!$B:$B, K$13) + SUMIFS(BANK!$E:$E, BANK!$D:$D,DEPARTMENTS!$B:$B, BANK!$B:$B, K$13, BANK!$B:$B, K$13) + SUMIFS(TRUST!$E:$E, TRUST!$D:$D,DEPARTMENTS!$B:$B, TRUST!$B:$B, K$13, TRUST!$B:$B, K$13) -> 10700 | L2: =SUMIFS(COLLECTION!$E:$E, COLLECTION!$D:$D,DEPARTMENTS!$B:$B, COLLECTION!$B:$B, L$13, COLLECTION!$B:$B, L$13) + SUMIFS(BANK!$E:$E, BANK!$D:$D,DEPARTMENTS!$B:$B, BANK!$B:$B, L$13, BANK!$B:$B, L$13) + SUMIFS(TRUST!$E:$E, TRUST!$D:$D,DEPARTMENTS!$B:$B, TRUST!$B:$B, L$13, TRUST!$B:$B, L$13) -> 9160 | M2: =SUMIFS(COLLECTION!$E:$E, COLLECTION!$D:$D,DEPARTMENTS!$B:$B, COLLECTION!$B:$B, M$13, COLLECTION!$B:$B, M$13) + SUMIFS(BANK!$E:$E, BANK!$D:$D,DEPARTMENTS!$B:$B, BANK!$B:$B, M$13, BANK!$B:$B, M$13) + SUMIFS(TRUST!$E:$E, TRUST!$D:$D,DEPARTMENTS!$B:$B, TRUST!$B:$B, M$13, TRUST!$B:$B, M$13) -> 1885 | N2: =SUMIFS(COLLECTION!$E:$E, COLLECTION!$D:$D,DEPARTMENTS!$B:$B, COLLECTION!$B:$B, N$13, COLLECTION!$B:$B, N$13) + SUMIFS(BANK!$E:$E, BANK!$D:$D,DEPARTMENTS!$B:$B, BANK!$B:$B, N$13, BANK!$B:$B, N$13) + SUMIFS(TRUST!$E:$E, TRUST!$D:$D,DEPARTMENTS!$B:$B, TRUST!$B:$B, N$13, TRUST!$B:$B, N$13) -> 0 | O2: =SUMIFS(COLLECTION!$E:$E, COLLECTION!$D:$D,DEPARTMENTS!$B:$B, COLLECTION!$B:$B, O$13, COLLECTION!$B:$B, O$13) + SUMIFS(BANK!$E:$E, BANK!$D:$D,DEPARTMENTS!$B:$B, BANK!$B:$B, O$13, BANK!$B:$B, O$13) + SUMIFS(TRUST!$E:$E, TRUST!$D:$D,DEPARTMENTS!$B:$B, TRUST!$B:$B, O$13, TRUST!$B:$B, O$13) -> 0 | ... S2: =SUMIFS(COLLECTION!$E:$E, COLLECTION!$D:$D,DEPARTMENTS!$B:$B, COLLECTION!$B:$B, S$13, COLLECTION!$B:$B, S$13) + SUMIFS(BANK!$E:$E, BANK!$D:$D,DEPARTMENTS!$B:$B, BANK!$B:$B, S$13, BANK!$B:$B, S$13) + SUMIFS(TRUST!$E:$E, TRUST!$D:$D,DEPARTMENTS!$B:$B, TRUST!$B:$B, S$13, TRUST!$B:$B, S$13) -> 0 | T2: =SUM(H2:S2) -> 49940 | AK2: =SUMIFS(COLLECTION!$E:$E, COLLECTION!$D:$D,DEPARTMENTS!$B:$B, COLLECTION!$B:$B, AK$12, COLLECTION!$C:$C, AK$13) + SUMIFS(BANK!$E:$E, BANK!$D:$D,DEPARTMENTS!$B:$B, BANK!$B:$B, AK$12, BANK!$C:$C, AK$13) + SUMIFS(TRUST!$E:$E, TRUST!$D:$D,DEPARTMENTS!$B:$B, TRUST!$B:$B, AK$12, TRUST!$C:$C, AK$13) -> 4685 | AL2: =SUMIFS(COLLECTION!$E:$E, COLLECTION!$D:$D,DEPARTMENTS!$B:$B, COLLECTION!$B:$B, AL$12, COLLECTION!$C:$C, AL$13) + SUMIFS(BANK!$E:$E, BANK!$D:$D,DEPARTMENTS!$B:$B, BANK!$B:$B, AL$12, BANK!$C:$C, AL$13) + SUMIFS(TRUST!$E:$E, TRUST!$D:$D,DEPARTMENTS!$B:$B, TRUST!$B:$B, AL$12, TRUST!$C:$C, AL$13) -> 2565 | AM2: =SUMIFS(COLLECTION!$E:$E, COLLECTION!$D:$D,DEPARTMENTS!$B:$B, COLLECTION!$B:$B, AM$12, COLLECTION!$C:$C, AM$13) + SUMIFS(BANK!$E:$E, BANK!$D:$D,DEPARTMENTS!$B:$B, BANK!$B:$B, AM$12, BANK!$C:$C, AM$13) + SUMIFS(TRUST!$E:$E, TRUST!$D:$D,DEPARTMENTS!$B:$B, TRUST!$B:$B, AM$12, TRUST!$C:$C, AM$13) -> 2765 | AN2: =SUMIFS(COLLECTION!$E:$E, COLLECTION!$D:$D,DEPARTMENTS!$B:$B, COLLECTION!$B:$B, AN$12, COLLECTION!$C:$C, AN$13) + SUMIFS(BANK!$E:$E, BANK!$D:$D,DEPARTMENTS!$B:$B, BANK!$B:$B, AN$12, BANK!$C:$C, AN$13) + SUMIFS(TRUST!$E:$E, TRUST!$D:$D,DEPARTMENTS!$B:$B, TRUST!$B:$B, AN$12, TRUST!$C:$C, AN$13) -> 2080 | AO2: =SUMIFS(COLLECTION!$E:$E, COLLECTION!$D:$D,DEPARTMENTS!$B:$B, COLLECTION!$B:$B, AO$12, COLLECTION!$C:$C, AO$13) + SUMIFS(BANK!$E:$E, BANK!$D:$D,DEPARTMENTS!$B:$B, BANK!$B:$B, AO$12, BANK!$C:$C, AO$13) + SUMIFS(TRUST!$E:$E, TRUST!$D:$D,DEPARTMENTS!$B:$B, TRUST!$B:$B, AO$12, TRUST!$C:$C, AO$13) -> 0 | AP2: =SUMIFS(COLLECTION!$E:$E, COLLECTION!$D:$D,DEPARTMENTS!$B:$B, COLLECTION!$B:$B, AP$12, COLLECTION!$C:$C, AP$13) + SUMIFS(BANK!$E:$E, BANK!$D:$D,DEPARTMENTS!$B:$B, BANK!$B:$B, AP$12, BANK!$C:$C, AP$13) + SUMIFS(TRUST!$E:$E, TRUST!$D:$D,DEPARTMENTS!$B:$B, TRUST!$B:$B, AP$12, TRUST!$C:$C, AP$13) -> 2015 | AQ2: =SUMIFS(COLLECTION!$E:$E, COLLECTION!$D:$D,DEPARTMENTS!$B:$B, COLLECTION!$B:$B, AQ$12, COLLECTION!$C:$C, AQ$13) + SUMIFS(BANK!$E:$E, BANK!$D:$D,DEPARTMENTS!$B:$B, BANK!$B:$B, AQ$12, BANK!$C:$C, AQ$13) + SUMIFS(TRUST!$E:$E, TRUST!$D:$D,DEPARTMENTS!$B:$B, TRUST!$B:$B, AQ$12, TRUST!$C:$C, AQ$13) -> 2370 | AR2: =SUMIFS(COLLECTION!$E:$E, COLLECTION!$D:$D,DEPARTMENTS!$B:$B, COLLECTION!$B:$B, AR$12, COLLECTION!$C:$C, AR$13) + SUMIFS(BANK!$E:$E, BANK!$D:$D,DEPARTMENTS!$B:$B, BANK!$B:$B, AR$12, BANK!$C:$C, AR$13) + SUMIFS(TRUST!$E:$E, TRUST!$D:$D,DEPARTMENTS!$B:$B, TRUST!$B:$B, AR$12, TRUST!$C:$C, AR$13) -> 2215 | ... BC2: =SUMIFS(COLLECTION!$E:$E, COLLECTION!$D:$D,DEPARTMENTS!$B:$B, COLLECTION!$B:$B, BC$12, COLLECTION!$C:$C, BC$13) + SUMIFS(BANK!$E:$E, BANK!$D:$D,DEPARTMENTS!$B:$B, BANK!$B:$B, BC$12, BANK!$C:$C, BC$13) + SUMIFS(TRUST!$E:$E, TRUST!$D:$D,DEPARTMENTS!$B:$B, TRUST!$B:$B, BC$12, TRUST!$C:$C, BC$13) -> 2130 | BE2: =SUMIFS(COLLECTION!$E:$E, COLLECTION!$D:$D,DEPARTMENTS!$B:$B, COLLECTION!$B:$B, BE$12, COLLECTION!$C:$C, BE$13) + SUMIFS(BANK!$E:$E, BANK!$D:$D,DEPARTMENTS!$B:$B, BANK!$B:$B, BE$12, BANK!$C:$C, BE$13) + SUMIFS(TRUST!$E:$E, TRUST!$D:$D,DEPARTMENTS!$B:$B, TRUST!$B:$B, BE$12, TRUST!$C:$C, BE$13) -> 2130 | BF2: =SUMIFS(COLLECTION!$E:$E, COLLECTION!$D:$D,DEPARTMENTS!$B:$B, COLLECTION!$B:$B, BF$12, COLLECTION!$C:$C, BF$13) + SUMIFS(BANK!$E:$E, BANK!$D:$D,DEPARTMENTS!$B:$B, BANK!$B:$B, BF$12, BANK!$C:$C, BF$13) + SUMIFS(TRUST!$E:$E, TRUST!$D:$D,DEPARTMENTS!$B:$B, TRUST!$B:$B, BF$12, TRUST!$C:$C, BF$13) -> 2490 | BG2: =SUMIFS(COLLECTION!$E:$E, COLLECTION!$D:$D,DEPARTMENTS!$B:$B, COLLECTION!$B:$B, BG$12, COLLECTION!$C:$C, BG$13) + SUMIFS(BANK!$E:$E, BANK!$D:$D,DEPARTMENTS!$B:$B, BANK!$B:$B, BG$12, BANK!$C:$C, BG$13) + SUMIFS(TRUST!$E:$E, TRUST!$D:$D,DEPARTMENTS!$B:$B, TRUST!$B:$B, BG$12, TRUST!$C:$C, BG$13) -> 1900 | BH2: =SUMIFS(COLLECTION!$E:$E, COLLECTION!$D:$D,DEPARTMENTS!$B:$B, COLLECTION!$B:$B, BH$12, COLLECTION!$C:$C, BH$13) + SUMIFS(BANK!$E:$E, BANK!$D:$D,DEPARTMENTS!$B:$B, BANK!$B:$B, BH$12, BANK!$C:$C, BH$13) + SUMIFS(TRUST!$E:$E, TRUST!$D:$D,DEPARTMENTS!$B:$B, TRUST!$B:$B, BH$12, TRUST!$C:$C, BH$13) -> 1195 | BI2: =SUMIFS(COLLECTION!$E:$E, COLLECTION!$D:$D,DEPARTMENTS!$B:$B, COLLECTION!$B:$B, BI$12, COLLECTION!$C:$C, BI$13) + SUMIFS(BANK!$E:$E, BANK!$D:$D,DEPARTMENTS!$B:$B, BANK!$B:$B, BI$12, BANK!$C:$C, BI$13) + SUMIFS(TRUST!$E:$E, TRUST!$D:$D,DEPARTMENTS!$B:$B, TRUST!$B:$B, BI$12, TRUST!$C:$C, BI$13) -> 1445 | BJ2: =SUMIFS(COLLECTION!$E:$E, COLLECTION!$D:$D,DEPARTMENTS!$B:$B, COLLECTION!$B:$B, BJ$12, COLLECTION!$C:$C, BJ$13) + SUMIFS(BANK!$E:$E, BANK!$D:$D,DEPARTMENTS!$B:$B, BANK!$B:$B, BJ$12, BANK!$C:$C, BJ$13) + SUMIFS(TRUST!$E:$E, TRUST!$D:$D,DEPARTMENTS!$B:$B, TRUST!$B:$B, BJ$12, TRUST!$C:$C, BJ$13) -> 100 | BK2: =SUMIFS(COLLECTION!$E:$E, COLLECTION!$D:$D,DEPARTMENTS!$B:$B, COLLECTION!$B:$B, BK$12, COLLECTION!$C:$C, BK$13) + SUMIFS(BANK!$E:$E, BANK!$D:$D,DEPARTMENTS!$B:$B, BANK!$B:$B, BK$12, BANK!$C:$C, BK$13) + SUMIFS(TRUST!$E:$E, TRUST!$D:$D,DEPARTMENTS!$B:$B, TRUST!$B:$B, BK$12, TRUST!$C:$C, BK$13) -> 0 | BL2: =SUMIFS(COLLECTION!$E:$E, COLLECTION!$D:$D,DEPARTMENTS!$B:$B, COLLECTION!$B:$B, BL$12, COLLECTION!$C:$C, BL$13) + SUMIFS(BANK!$E:$E, BANK!$D:$D,DEPARTMENTS!$B:$B, BANK!$B:$B, BL$12, BANK!$C:$C, BL$13) + SUMIFS(TRUST!$E:$E, TRUST!$D:$D,DEPARTMENTS!$B:$B, TRUST!$B:$B, BL$12, TRUST!$C:$C, BL$13) -> 0 | ... CQ2: =SUMIFS(COLLECTION!$E:$E, COLLECTION!$D:$D,DEPARTMENTS!$B:$B, COLLECTION!$B:$B, CQ$12, COLLECTION!$C:$C, CQ$13) + SUMIFS(BANK!$E:$E, BANK!$D:$D,DEPARTMENTS!$B:$B, BANK!$B:$B, CQ$12, BANK!$C:$C, CQ$13) + SUMIFS(TRUST!$E:$E, TRUST!$D:$D,DEPARTMENTS!$B:$B, TRUST!$B:$B, CQ$12, TRUST!$C:$C, CQ$13) -> 0 | CR2: =SUM(AK2:CQ2) -> 48155
B3: LOOSE OFFERING | C3: 0 | D3: =SUMIF(COLLECTION!D:D,DEPARTMENTS!B:B,COLLECTION!E:E)+SUMIF(BANK!D:D,DEPARTMENTS!B:B,BANK!E:E)+SUMIF(TRUST!D:D,DEPARTMENTS!B:B,TRUST!E:E) -> 130359 | H3: =SUMIFS(COLLECTION!$E:$E, COLLECTION!$D:$D,DEPARTMENTS!$B:$B, COLLECTION!$B:$B, H$13, COLLECTION!$B:$B, H$13) + SUMIFS(BANK!$E:$E, BANK!$D:$D,DEPARTMENTS!$B:$B, BANK!$B:$B, H$13, BANK!$B:$B, H$13) + SUMIFS(TRUST!$E:$E, TRUST!$D:$D,DEPARTMENTS!$B:$B, TRUST!$B:$B, H$13, TRUST!$B:$B, H$13) -> 33134 | I3: =SUMIFS(COLLECTION!$E:$E, COLLECTION!$D:$D,DEPARTMENTS!$B:$B, COLLECTION!$B:$B, I$13, COLLECTION!$B:$B, I$13) + SUMIFS(BANK!$E:$E, BANK!$D:$D,DEPARTMENTS!$B:$B, BANK!$B:$B, I$13, BANK!$B:$B, I$13) + SUMIFS(TRUST!$E:$E, TRUST!$D:$D,DEPARTMENTS!$B:$B, TRUST!$B:$B, I$13, TRUST!$B:$B, I$13) -> 20463 | J3: =SUMIFS(COLLECTION!$E:$E, COLLECTION!$D:$D,DEPARTMENTS!$B:$B, COLLECTION!$B:$B, J$13, COLLECTION!$B:$B, J$13) + SUMIFS(BANK!$E:$E, BANK!$D:$D,DEPARTMENTS!$B:$B, BANK!$B:$B, J$13, BANK!$B:$B, J$13) + SUMIFS(TRUST!$E:$E, TRUST!$D:$D,DEPARTMENTS!$B:$B, TRUST!$B:$B, J$13, TRUST!$B:$B, J$13) -> 15935 | K3: =SUMIFS(COLLECTION!$E:$E, COLLECTION!$D:$D,DEPARTMENTS!$B:$B, COLLECTION!$B:$B, K$13, COLLECTION!$B:$B, K$13) + SUMIFS(BANK!$E:$E, BANK!$D:$D,DEPARTMENTS!$B:$B, BANK!$B:$B, K$13, BANK!$B:$B, K$13) + SUMIFS(TRUST!$E:$E, TRUST!$D:$D,DEPARTMENTS!$B:$B, TRUST!$B:$B, K$13, TRUST!$B:$B, K$13) -> 25786 | L3: =SUMIFS(COLLECTION!$E:$E, COLLECTION!$D:$D,DEPARTMENTS!$B:$B, COLLECTION!$B:$B, L$13, COLLECTION!$B:$B, L$13) + SUMIFS(BANK!$E:$E, BANK!$D:$D,DEPARTMENTS!$B:$B, BANK!$B:$B, L$13, BANK!$B:$B, L$13) + SUMIFS(TRUST!$E:$E, TRUST!$D:$D,DEPARTMENTS!$B:$B, TRUST!$B:$B, L$13, TRUST!$B:$B, L$13) -> 28805 | M3: =SUMIFS(COLLECTION!$E:$E, COLLECTION!$D:$D,DEPARTMENTS!$B:$B, COLLECTION!$B:$B, M$13, COLLECTION!$B:$B, M$13) + SUMIFS(BANK!$E:$E, BANK!$D:$D,DEPARTMENTS!$B:$B, BANK!$B:$B, M$13, BANK!$B:$B, M$13) + SUMIFS(TRUST!$E:$E, TRUST!$D:$D,DEPARTMENTS!$B:$B, TRUST!$B:$B, M$13, TRUST!$B:$B, M$13) -> 6236 | N3: =SUMIFS(COLLECTION!$E:$E, COLLECTION!$D:$D,DEPARTMENTS!$B:$B, COLLECTION!$B:$B, N$13, COLLECTION!$B:$B, N$13) + SUMIFS(BANK!$E:$E, BANK!$D:$D,DEPARTMENTS!$B:$B, BANK!$B:$B, N$13, BANK!$B:$B, N$13) + SUMIFS(TRUST!$E:$E, TRUST!$D:$D,DEPARTMENTS!$B:$B, TRUST!$B:$B, N$13, TRUST!$B:$B, N$13) -> 0 | O3: =SUMIFS(COLLECTION!$E:$E, COLLECTION!$D:$D,DEPARTMENTS!$B:$B, COLLECTION!$B:$B, O$13, COLLECTION!$B:$B, O$13) + SUMIFS(BANK!$E:$E, BANK!$D:$D,DEPARTMENTS!$B:$B, BANK!$B:$B, O$13, BANK!$B:$B, O$13) + SUMIFS(TRUST!$E:$E, TRUST!$D:$D,DEPARTMENTS!$B:$B, TRUST!$B:$B, O$13, TRUST!$B:$B, O$13) -> 0 | ... S3: =SUMIFS(COLLECTION!$E:$E, COLLECTION!$D:$D,DEPARTMENTS!$B:$B, COLLECTION!$B:$B, S$13, COLLECTION!$B:$B, S$13) + SUMIFS(BANK!$E:$E, BANK!$D:$D,DEPARTMENTS!$B:$B, BANK!$B:$B, S$13, BANK!$B:$B, S$13) + SUMIFS(TRUST!$E:$E, TRUST!$D:$D,DEPARTMENTS!$B:$B, TRUST!$B:$B, S$13, TRUST!$B:$B, S$13) -> 0 | T3: =SUM(H3:S3) -> 130359 | AK3: =SUMIFS(COLLECTION!$E:$E, COLLECTION!$D:$D,DEPARTMENTS!$B:$B, COLLECTION!$B:$B, AK$12, COLLECTION!$C:$C, AK$13) + SUMIFS(BANK!$E:$E, BANK!$D:$D,DEPARTMENTS!$B:$B, BANK!$B:$B, AK$12, BANK!$C:$C, AK$13) + SUMIFS(TRUST!$E:$E, TRUST!$D:$D,DEPARTMENTS!$B:$B, TRUST!$B:$B, AK$12, TRUST!$C:$C, AK$13) -> 15662 | AL3: =SUMIFS(COLLECTION!$E:$E, COLLECTION!$D:$D,DEPARTMENTS!$B:$B, COLLECTION!$B:$B, AL$12, COLLECTION!$C:$C, AL$13) + SUMIFS(BANK!$E:$E, BANK!$D:$D,DEPARTMENTS!$B:$B, BANK!$B:$B, AL$12, BANK!$C:$C, AL$13) + SUMIFS(TRUST!$E:$E, TRUST!$D:$D,DEPARTMENTS!$B:$B, TRUST!$B:$B, AL$12, TRUST!$C:$C, AL$13) -> 7012 | AM3: =SUMIFS(COLLECTION!$E:$E, COLLECTION!$D:$D,DEPARTMENTS!$B:$B, COLLECTION!$B:$B, AM$12, COLLECTION!$C:$C, AM$13) + SUMIFS(BANK!$E:$E, BANK!$D:$D,DEPARTMENTS!$B:$B, BANK!$B:$B, AM$12, BANK!$C:$C, AM$13) + SUMIFS(TRUST!$E:$E, TRUST!$D:$D,DEPARTMENTS!$B:$B, TRUST!$B:$B, AM$12, TRUST!$C:$C, AM$13) -> 5775 | AN3: =SUMIFS(COLLECTION!$E:$E, COLLECTION!$D:$D,DEPARTMENTS!$B:$B, COLLECTION!$B:$B, AN$12, COLLECTION!$C:$C, AN$13) + SUMIFS(BANK!$E:$E, BANK!$D:$D,DEPARTMENTS!$B:$B, BANK!$B:$B, AN$12, BANK!$C:$C, AN$13) + SUMIFS(TRUST!$E:$E, TRUST!$D:$D,DEPARTMENTS!$B:$B, TRUST!$B:$B, AN$12, TRUST!$C:$C, AN$13) -> 4685 | AO3: =SUMIFS(COLLECTION!$E:$E, COLLECTION!$D:$D,DEPARTMENTS!$B:$B, COLLECTION!$B:$B, AO$12, COLLECTION!$C:$C, AO$13) + SUMIFS(BANK!$E:$E, BANK!$D:$D,DEPARTMENTS!$B:$B, BANK!$B:$B, AO$12, BANK!$C:$C, AO$13) + SUMIFS(TRUST!$E:$E, TRUST!$D:$D,DEPARTMENTS!$B:$B, TRUST!$B:$B, AO$12, TRUST!$C:$C, AO$13) -> 0 | AP3: =SUMIFS(COLLECTION!$E:$E, COLLECTION!$D:$D,DEPARTMENTS!$B:$B, COLLECTION!$B:$B, AP$12, COLLECTION!$C:$C, AP$13) + SUMIFS(BANK!$E:$E, BANK!$D:$D,DEPARTMENTS!$B:$B, BANK!$B:$B, AP$12, BANK!$C:$C, AP$13) + SUMIFS(TRUST!$E:$E, TRUST!$D:$D,DEPARTMENTS!$B:$B, TRUST!$B:$B, AP$12, TRUST!$C:$C, AP$13) -> 5230 | AQ3: =SUMIFS(COLLECTION!$E:$E, COLLECTION!$D:$D,DEPARTMENTS!$B:$B, COLLECTION!$B:$B, AQ$12, COLLECTION!$C:$C, AQ$13) + SUMIFS(BANK!$E:$E, BANK!$D:$D,DEPARTMENTS!$B:$B, BANK!$B:$B, AQ$12, BANK!$C:$C, AQ$13) + SUMIFS(TRUST!$E:$E, TRUST!$D:$D,DEPARTMENTS!$B:$B, TRUST!$B:$B, AQ$12, TRUST!$C:$C, AQ$13) -> 4723 | AR3: =SUMIFS(COLLECTION!$E:$E, COLLECTION!$D:$D,DEPARTMENTS!$B:$B, COLLECTION!$B:$B, AR$12, COLLECTION!$C:$C, AR$13) + SUMIFS(BANK!$E:$E, BANK!$D:$D,DEPARTMENTS!$B:$B, BANK!$B:$B, AR$12, BANK!$C:$C, AR$13) + SUMIFS(TRUST!$E:$E, TRUST!$D:$D,DEPARTMENTS!$B:$B, TRUST!$B:$B, AR$12, TRUST!$C:$C, AR$13) -> 4590 | ... BC3: =SUMIFS(COLLECTION!$E:$E, COLLECTION!$D:$D,DEPARTMENTS!$B:$B, COLLECTION!$B:$B, BC$12, COLLECTION!$C:$C, BC$13) + SUMIFS(BANK!$E:$E, BANK!$D:$D,DEPARTMENTS!$B:$B, BANK!$B:$B, BC$12, BANK!$C:$C, BC$13) + SUMIFS(TRUST!$E:$E, TRUST!$D:$D,DEPARTMENTS!$B:$B, TRUST!$B:$B, BC$12, TRUST!$C:$C, BC$13) -> 7355 | BE3: =SUMIFS(COLLECTION!$E:$E, COLLECTION!$D:$D,DEPARTMENTS!$B:$B, COLLECTION!$B:$B, BE$12, COLLECTION!$C:$C, BE$13) + SUMIFS(BANK!$E:$E, BANK!$D:$D,DEPARTMENTS!$B:$B, BANK!$B:$B, BE$12, BANK!$C:$C, BE$13) + SUMIFS(TRUST!$E:$E, TRUST!$D:$D,DEPARTMENTS!$B:$B, TRUST!$B:$B, BE$12, TRUST!$C:$C, BE$13) -> 7175 | BF3: =SUMIFS(COLLECTION!$E:$E, COLLECTION!$D:$D,DEPARTMENTS!$B:$B, COLLECTION!$B:$B, BF$12, COLLECTION!$C:$C, BF$13) + SUMIFS(BANK!$E:$E, BANK!$D:$D,DEPARTMENTS!$B:$B, BANK!$B:$B, BF$12, BANK!$C:$C, BF$13) + SUMIFS(TRUST!$E:$E, TRUST!$D:$D,DEPARTMENTS!$B:$B, TRUST!$B:$B, BF$12, TRUST!$C:$C, BF$13) -> 6285 | BG3: =SUMIFS(COLLECTION!$E:$E, COLLECTION!$D:$D,DEPARTMENTS!$B:$B, COLLECTION!$B:$B, BG$12, COLLECTION!$C:$C, BG$13) + SUMIFS(BANK!$E:$E, BANK!$D:$D,DEPARTMENTS!$B:$B, BANK!$B:$B, BG$12, BANK!$C:$C, BG$13) + SUMIFS(TRUST!$E:$E, TRUST!$D:$D,DEPARTMENTS!$B:$B, TRUST!$B:$B, BG$12, TRUST!$C:$C, BG$13) -> 3925 | BH3: =SUMIFS(COLLECTION!$E:$E, COLLECTION!$D:$D,DEPARTMENTS!$B:$B, COLLECTION!$B:$B, BH$12, COLLECTION!$C:$C, BH$13) + SUMIFS(BANK!$E:$E, BANK!$D:$D,DEPARTMENTS!$B:$B, BANK!$B:$B, BH$12, BANK!$C:$C, BH$13) + SUMIFS(TRUST!$E:$E, TRUST!$D:$D,DEPARTMENTS!$B:$B, TRUST!$B:$B, BH$12, TRUST!$C:$C, BH$13) -> 6550 | BI3: =SUMIFS(COLLECTION!$E:$E, COLLECTION!$D:$D,DEPARTMENTS!$B:$B, COLLECTION!$B:$B, BI$12, COLLECTION!$C:$C, BI$13) + SUMIFS(BANK!$E:$E, BANK!$D:$D,DEPARTMENTS!$B:$B, BANK!$B:$B, BI$12, BANK!$C:$C, BI$13) + SUMIFS(TRUST!$E:$E, TRUST!$D:$D,DEPARTMENTS!$B:$B, TRUST!$B:$B, BI$12, TRUST!$C:$C, BI$13) -> 4870 | BJ3: =SUMIFS(COLLECTION!$E:$E, COLLECTION!$D:$D,DEPARTMENTS!$B:$B, COLLECTION!$B:$B, BJ$12, COLLECTION!$C:$C, BJ$13) + SUMIFS(BANK!$E:$E, BANK!$D:$D,DEPARTMENTS!$B:$B, BANK!$B:$B, BJ$12, BANK!$C:$C, BJ$13) + SUMIFS(TRUST!$E:$E, TRUST!$D:$D,DEPARTMENTS!$B:$B, TRUST!$B:$B, BJ$12, TRUST!$C:$C, BJ$13) -> 0 | BK3: =SUMIFS(COLLECTION!$E:$E, COLLECTION!$D:$D,DEPARTMENTS!$B:$B, COLLECTION!$B:$B, BK$12, COLLECTION!$C:$C, BK$13) + SUMIFS(BANK!$E:$E, BANK!$D:$D,DEPARTMENTS!$B:$B, BANK!$B:$B, BK$12, BANK!$C:$C, BK$13) + SUMIFS(TRUST!$E:$E, TRUST!$D:$D,DEPARTMENTS!$B:$B, TRUST!$B:$B, BK$12, TRUST!$C:$C, BK$13) -> 0 | BL3: =SUMIFS(COLLECTION!$E:$E, COLLECTION!$D:$D,DEPARTMENTS!$B:$B, COLLECTION!$B:$B, BL$12, COLLECTION!$C:$C, BL$13) + SUMIFS(BANK!$E:$E, BANK!$D:$D,DEPARTMENTS!$B:$B, BANK!$B:$B, BL$12, BANK!$C:$C, BL$13) + SUMIFS(TRUST!$E:$E, TRUST!$D:$D,DEPARTMENTS!$B:$B, TRUST!$B:$B, BL$12, TRUST!$C:$C, BL$13) -> 0 | ... CQ3: =SUMIFS(COLLECTION!$E:$E, COLLECTION!$D:$D,DEPARTMENTS!$B:$B, COLLECTION!$B:$B, CQ$12, COLLECTION!$C:$C, CQ$13) + SUMIFS(BANK!$E:$E, BANK!$D:$D,DEPARTMENTS!$B:$B, BANK!$B:$B, CQ$12, BANK!$C:$C, CQ$13) + SUMIFS(TRUST!$E:$E, TRUST!$D:$D,DEPARTMENTS!$B:$B, TRUST!$B:$B, CQ$12, TRUST!$C:$C, CQ$13) -> 0 | CR3: =SUM(AK3:CQ3) -> 124123
B4: COMBINED - LCB | C4: 0 | D4: =SUMIF(COLLECTION!D:D,DEPARTMENTS!B:B,COLLECTION!E:E)+SUMIF(BANK!D:D,DEPARTMENTS!B:B,BANK!E:E)+SUMIF(TRUST!D:D,DEPARTMENTS!B:B,TRUST!E:E) -> 107931.5 | H4: =SUMIFS(COLLECTION!$E:$E, COLLECTION!$D:$D,DEPARTMENTS!$B:$B, COLLECTION!$B:$B, H$13, COLLECTION!$B:$B, H$13) + SUMIFS(BANK!$E:$E, BANK!$D:$D,DEPARTMENTS!$B:$B, BANK!$B:$B, H$13, BANK!$B:$B, H$13) + SUMIFS(TRUST!$E:$E, TRUST!$D:$D,DEPARTMENTS!$B:$B, TRUST!$B:$B, H$13, TRUST!$B:$B, H$13) -> 27573 | I4: =SUMIFS(COLLECTION!$E:$E, COLLECTION!$D:$D,DEPARTMENTS!$B:$B, COLLECTION!$B:$B, I$13, COLLECTION!$B:$B, I$13) + SUMIFS(BANK!$E:$E, BANK!$D:$D,DEPARTMENTS!$B:$B, BANK!$B:$B, I$13, BANK!$B:$B, I$13) + SUMIFS(TRUST!$E:$E, TRUST!$D:$D,DEPARTMENTS!$B:$B, TRUST!$B:$B, I$13, TRUST!$B:$B, I$13) -> 18746.5 | J4: =SUMIFS(COLLECTION!$E:$E, COLLECTION!$D:$D,DEPARTMENTS!$B:$B, COLLECTION!$B:$B, J$13, COLLECTION!$B:$B, J$13) + SUMIFS(BANK!$E:$E, BANK!$D:$D,DEPARTMENTS!$B:$B, BANK!$B:$B, J$13, BANK!$B:$B, J$13) + SUMIFS(TRUST!$E:$E, TRUST!$D:$D,DEPARTMENTS!$B:$B, TRUST!$B:$B, J$13, TRUST!$B:$B, J$13) -> 15955.5 | K4: =SUMIFS(COLLECTION!$E:$E, COLLECTION!$D:$D,DEPARTMENTS!$B:$B, COLLECTION!$B:$B, K$13, COLLECTION!$B:$B, K$13) + SUMIFS(BANK!$E:$E, BANK!$D:$D,DEPARTMENTS!$B:$B, BANK!$B:$B, K$13, BANK!$B:$B, K$13) + SUMIFS(TRUST!$E:$E, TRUST!$D:$D,DEPARTMENTS!$B:$B, TRUST!$B:$B, K$13, TRUST!$B:$B, K$13) -> 19379.5 | L4: =SUMIFS(COLLECTION!$E:$E, COLLECTION!$D:$D,DEPARTMENTS!$B:$B, COLLECTION!$B:$B, L$13, COLLECTION!$B:$B, L$13) + SUMIFS(BANK!$E:$E, BANK!$D:$D,DEPARTMENTS!$B:$B, BANK!$B:$B, L$13, BANK!$B:$B, L$13) + SUMIFS(TRUST!$E:$E, TRUST!$D:$D,DEPARTMENTS!$B:$B, TRUST!$B:$B, L$13, TRUST!$B:$B, L$13) -> 23284.5 | M4: =SUMIFS(COLLECTION!$E:$E, COLLECTION!$D:$D,DEPARTMENTS!$B:$B, COLLECTION!$B:$B, M$13, COLLECTION!$B:$B, M$13) + SUMIFS(BANK!$E:$E, BANK!$D:$D,DEPARTMENTS!$B:$B, BANK!$B:$B, M$13, BANK!$B:$B, M$13) + SUMIFS(TRUST!$E:$E, TRUST!$D:$D,DEPARTMENTS!$B:$B, TRUST!$B:$B, M$13, TRUST!$B:$B, M$13) -> 2992.5 | N4: =SUMIFS(COLLECTION!$E:$E, COLLECTION!$D:$D,DEPARTMENTS!$B:$B, COLLECTION!$B:$B, N$13, COLLECTION!$B:$B, N$13) + SUMIFS(BANK!$E:$E, BANK!$D:$D,DEPARTMENTS!$B:$B, BANK!$B:$B, N$13, BANK!$B:$B, N$13) + SUMIFS(TRUST!$E:$E, TRUST!$D:$D,DEPARTMENTS!$B:$B, TRUST!$B:$B, N$13, TRUST!$B:$B, N$13) -> 0 | O4: =SUMIFS(COLLECTION!$E:$E, COLLECTION!$D:$D,DEPARTMENTS!$B:$B, COLLECTION!$B:$B, O$13, COLLECTION!$B:$B, O$13) + SUMIFS(BANK!$E:$E, BANK!$D:$D,DEPARTMENTS!$B:$B, BANK!$B:$B, O$13, BANK!$B:$B, O$13) + SUMIFS(TRUST!$E:$E, TRUST!$D:$D,DEPARTMENTS!$B:$B, TRUST!$B:$B, O$13, TRUST!$B:$B, O$13) -> 0 | ... S4: =SUMIFS(COLLECTION!$E:$E, COLLECTION!$D:$D,DEPARTMENTS!$B:$B, COLLECTION!$B:$B, S$13, COLLECTION!$B:$B, S$13) + SUMIFS(BANK!$E:$E, BANK!$D:$D,DEPARTMENTS!$B:$B, BANK!$B:$B, S$13, BANK!$B:$B, S$13) + SUMIFS(TRUST!$E:$E, TRUST!$D:$D,DEPARTMENTS!$B:$B, TRUST!$B:$B, S$13, TRUST!$B:$B, S$13) -> 0 | T4: =SUM(H4:S4) -> 107931.5 | AK4: =SUMIFS(COLLECTION!$E:$E, COLLECTION!$D:$D,DEPARTMENTS!$B:$B, COLLECTION!$B:$B, AK$12, COLLECTION!$C:$C, AK$13) + SUMIFS(BANK!$E:$E, BANK!$D:$D,DEPARTMENTS!$B:$B, BANK!$B:$B, AK$12, BANK!$C:$C, AK$13) + SUMIFS(TRUST!$E:$E, TRUST!$D:$D,DEPARTMENTS!$B:$B, TRUST!$B:$B, AK$12, TRUST!$C:$C, AK$13) -> 5200 | AL4: =SUMIFS(COLLECTION!$E:$E, COLLECTION!$D:$D,DEPARTMENTS!$B:$B, COLLECTION!$B:$B, AL$12, COLLECTION!$C:$C, AL$13) + SUMIFS(BANK!$E:$E, BANK!$D:$D,DEPARTMENTS!$B:$B, BANK!$B:$B, AL$12, BANK!$C:$C, AL$13) + SUMIFS(TRUST!$E:$E, TRUST!$D:$D,DEPARTMENTS!$B:$B, TRUST!$B:$B, AL$12, TRUST!$C:$C, AL$13) -> 4330 | AM4: =SUMIFS(COLLECTION!$E:$E, COLLECTION!$D:$D,DEPARTMENTS!$B:$B, COLLECTION!$B:$B, AM$12, COLLECTION!$C:$C, AM$13) + SUMIFS(BANK!$E:$E, BANK!$D:$D,DEPARTMENTS!$B:$B, BANK!$B:$B, AM$12, BANK!$C:$C, AM$13) + SUMIFS(TRUST!$E:$E, TRUST!$D:$D,DEPARTMENTS!$B:$B, TRUST!$B:$B, AM$12, TRUST!$C:$C, AM$13) -> 6376.5 | AN4: =SUMIFS(COLLECTION!$E:$E, COLLECTION!$D:$D,DEPARTMENTS!$B:$B, COLLECTION!$B:$B, AN$12, COLLECTION!$C:$C, AN$13) + SUMIFS(BANK!$E:$E, BANK!$D:$D,DEPARTMENTS!$B:$B, BANK!$B:$B, AN$12, BANK!$C:$C, AN$13) + SUMIFS(TRUST!$E:$E, TRUST!$D:$D,DEPARTMENTS!$B:$B, TRUST!$B:$B, AN$12, TRUST!$C:$C, AN$13) -> 5617.5 | AO4: =SUMIFS(COLLECTION!$E:$E, COLLECTION!$D:$D,DEPARTMENTS!$B:$B, COLLECTION!$B:$B, AO$12, COLLECTION!$C:$C, AO$13) + SUMIFS(BANK!$E:$E, BANK!$D:$D,DEPARTMENTS!$B:$B, BANK!$B:$B, AO$12, BANK!$C:$C, AO$13) + SUMIFS(TRUST!$E:$E, TRUST!$D:$D,DEPARTMENTS!$B:$B, TRUST!$B:$B, AO$12, TRUST!$C:$C, AO$13) -> 6049 | AP4: =SUMIFS(COLLECTION!$E:$E, COLLECTION!$D:$D,DEPARTMENTS!$B:$B, COLLECTION!$B:$B, AP$12, COLLECTION!$C:$C, AP$13) + SUMIFS(BANK!$E:$E, BANK!$D:$D,DEPARTMENTS!$B:$B, BANK!$B:$B, AP$12, BANK!$C:$C, AP$13) + SUMIFS(TRUST!$E:$E, TRUST!$D:$D,DEPARTMENTS!$B:$B, TRUST!$B:$B, AP$12, TRUST!$C:$C, AP$13) -> 2834.5 | AQ4: =SUMIFS(COLLECTION!$E:$E, COLLECTION!$D:$D,DEPARTMENTS!$B:$B, COLLECTION!$B:$B, AQ$12, COLLECTION!$C:$C, AQ$13) + SUMIFS(BANK!$E:$E, BANK!$D:$D,DEPARTMENTS!$B:$B, BANK!$B:$B, AQ$12, BANK!$C:$C, AQ$13) + SUMIFS(TRUST!$E:$E, TRUST!$D:$D,DEPARTMENTS!$B:$B, TRUST!$B:$B, AQ$12, TRUST!$C:$C, AQ$13) -> 8829.5 | AR4: =SUMIFS(COLLECTION!$E:$E, COLLECTION!$D:$D,DEPARTMENTS!$B:$B, COLLECTION!$B:$B, AR$12, COLLECTION!$C:$C, AR$13) + SUMIFS(BANK!$E:$E, BANK!$D:$D,DEPARTMENTS!$B:$B, BANK!$B:$B, AR$12, BANK!$C:$C, AR$13) + SUMIFS(TRUST!$E:$E, TRUST!$D:$D,DEPARTMENTS!$B:$B, TRUST!$B:$B, AR$12, TRUST!$C:$C, AR$13) -> 3627.5 | ... BC4: =SUMIFS(COLLECTION!$E:$E, COLLECTION!$D:$D,DEPARTMENTS!$B:$B, COLLECTION!$B:$B, BC$12, COLLECTION!$C:$C, BC$13) + SUMIFS(BANK!$E:$E, BANK!$D:$D,DEPARTMENTS!$B:$B, BANK!$B:$B, BC$12, BANK!$C:$C, BC$13) + SUMIFS(TRUST!$E:$E, TRUST!$D:$D,DEPARTMENTS!$B:$B, TRUST!$B:$B, BC$12, TRUST!$C:$C, BC$13) -> 4310 | BE4: =SUMIFS(COLLECTION!$E:$E, COLLECTION!$D:$D,DEPARTMENTS!$B:$B, COLLECTION!$B:$B, BE$12, COLLECTION!$C:$C, BE$13) + SUMIFS(BANK!$E:$E, BANK!$D:$D,DEPARTMENTS!$B:$B, BANK!$B:$B, BE$12, BANK!$C:$C, BE$13) + SUMIFS(TRUST!$E:$E, TRUST!$D:$D,DEPARTMENTS!$B:$B, TRUST!$B:$B, BE$12, TRUST!$C:$C, BE$13) -> 5185 | BF4: =SUMIFS(COLLECTION!$E:$E, COLLECTION!$D:$D,DEPARTMENTS!$B:$B, COLLECTION!$B:$B, BF$12, COLLECTION!$C:$C, BF$13) + SUMIFS(BANK!$E:$E, BANK!$D:$D,DEPARTMENTS!$B:$B, BANK!$B:$B, BF$12, BANK!$C:$C, BF$13) + SUMIFS(TRUST!$E:$E, TRUST!$D:$D,DEPARTMENTS!$B:$B, TRUST!$B:$B, BF$12, TRUST!$C:$C, BF$13) -> 5347 | BG4: =SUMIFS(COLLECTION!$E:$E, COLLECTION!$D:$D,DEPARTMENTS!$B:$B, COLLECTION!$B:$B, BG$12, COLLECTION!$C:$C, BG$13) + SUMIFS(BANK!$E:$E, BANK!$D:$D,DEPARTMENTS!$B:$B, BANK!$B:$B, BG$12, BANK!$C:$C, BG$13) + SUMIFS(TRUST!$E:$E, TRUST!$D:$D,DEPARTMENTS!$B:$B, TRUST!$B:$B, BG$12, TRUST!$C:$C, BG$13) -> 7582.5 | BH4: =SUMIFS(COLLECTION!$E:$E, COLLECTION!$D:$D,DEPARTMENTS!$B:$B, COLLECTION!$B:$B, BH$12, COLLECTION!$C:$C, BH$13) + SUMIFS(BANK!$E:$E, BANK!$D:$D,DEPARTMENTS!$B:$B, BANK!$B:$B, BH$12, BANK!$C:$C, BH$13) + SUMIFS(TRUST!$E:$E, TRUST!$D:$D,DEPARTMENTS!$B:$B, TRUST!$B:$B, BH$12, TRUST!$C:$C, BH$13) -> 2525 | BI4: =SUMIFS(COLLECTION!$E:$E, COLLECTION!$D:$D,DEPARTMENTS!$B:$B, COLLECTION!$B:$B, BI$12, COLLECTION!$C:$C, BI$13) + SUMIFS(BANK!$E:$E, BANK!$D:$D,DEPARTMENTS!$B:$B, BANK!$B:$B, BI$12, BANK!$C:$C, BI$13) + SUMIFS(TRUST!$E:$E, TRUST!$D:$D,DEPARTMENTS!$B:$B, TRUST!$B:$B, BI$12, TRUST!$C:$C, BI$13) -> 2645 | BJ4: =SUMIFS(COLLECTION!$E:$E, COLLECTION!$D:$D,DEPARTMENTS!$B:$B, COLLECTION!$B:$B, BJ$12, COLLECTION!$C:$C, BJ$13) + SUMIFS(BANK!$E:$E, BANK!$D:$D,DEPARTMENTS!$B:$B, BANK!$B:$B, BJ$12, BANK!$C:$C, BJ$13) + SUMIFS(TRUST!$E:$E, TRUST!$D:$D,DEPARTMENTS!$B:$B, TRUST!$B:$B, BJ$12, TRUST!$C:$C, BJ$13) -> 2992.5 | BK4: =SUMIFS(COLLECTION!$E:$E, COLLECTION!$D:$D,DEPARTMENTS!$B:$B, COLLECTION!$B:$B, BK$12, COLLECTION!$C:$C, BK$13) + SUMIFS(BANK!$E:$E, BANK!$D:$D,DEPARTMENTS!$B:$B, BANK!$B:$B, BK$12, BANK!$C:$C, BK$13) + SUMIFS(TRUST!$E:$E, TRUST!$D:$D,DEPARTMENTS!$B:$B, TRUST!$B:$B, BK$12, TRUST!$C:$C, BK$13) -> 0 | BL4: =SUMIFS(COLLECTION!$E:$E, COLLECTION!$D:$D,DEPARTMENTS!$B:$B, COLLECTION!$B:$B, BL$12, COLLECTION!$C:$C, BL$13) + SUMIFS(BANK!$E:$E, BANK!$D:$D,DEPARTMENTS!$B:$B, BANK!$B:$B, BL$12, BANK!$C:$C, BL$13) + SUMIFS(TRUST!$E:$E, TRUST!$D:$D,DEPARTMENTS!$B:$B, TRUST!$B:$B, BL$12, TRUST!$C:$C, BL$13) -> 0 | ... CQ4: =SUMIFS(COLLECTION!$E:$E, COLLECTION!$D:$D,DEPARTMENTS!$B:$B, COLLECTION!$B:$B, CQ$12, COLLECTION!$C:$C, CQ$13) + SUMIFS(BANK!$E:$E, BANK!$D:$D,DEPARTMENTS!$B:$B, BANK!$B:$B, CQ$12, BANK!$C:$C, CQ$13) + SUMIFS(TRUST!$E:$E, TRUST!$D:$D,DEPARTMENTS!$B:$B, TRUST!$B:$B, CQ$12, TRUST!$C:$C, CQ$13) -> 0 | CR4: =SUM(AK4:CQ4) -> 107931.5
B5: THANKGIVING - LCB | C5: 0 | D5: =SUMIF(COLLECTION!D:D,DEPARTMENTS!B:B,COLLECTION!E:E)+SUMIF(BANK!D:D,DEPARTMENTS!B:B,BANK!E:E)+SUMIF(TRUST!D:D,DEPARTMENTS!B:B,TRUST!E:E) -> 39831 | H5: =SUMIFS(COLLECTION!$E:$E, COLLECTION!$D:$D,DEPARTMENTS!$B:$B, COLLECTION!$B:$B, H$13, COLLECTION!$B:$B, H$13) + SUMIFS(BANK!$E:$E, BANK!$D:$D,DEPARTMENTS!$B:$B, BANK!$B:$B, H$13, BANK!$B:$B, H$13) + SUMIFS(TRUST!$E:$E, TRUST!$D:$D,DEPARTMENTS!$B:$B, TRUST!$B:$B, H$13, TRUST!$B:$B, H$13) -> 19141 | I5: =SUMIFS(COLLECTION!$E:$E, COLLECTION!$D:$D,DEPARTMENTS!$B:$B, COLLECTION!$B:$B, I$13, COLLECTION!$B:$B, I$13) + SUMIFS(BANK!$E:$E, BANK!$D:$D,DEPARTMENTS!$B:$B, BANK!$B:$B, I$13, BANK!$B:$B, I$13) + SUMIFS(TRUST!$E:$E, TRUST!$D:$D,DEPARTMENTS!$B:$B, TRUST!$B:$B, I$13, TRUST!$B:$B, I$13) -> 6625 | J5: =SUMIFS(COLLECTION!$E:$E, COLLECTION!$D:$D,DEPARTMENTS!$B:$B, COLLECTION!$B:$B, J$13, COLLECTION!$B:$B, J$13) + SUMIFS(BANK!$E:$E, BANK!$D:$D,DEPARTMENTS!$B:$B, BANK!$B:$B, J$13, BANK!$B:$B, J$13) + SUMIFS(TRUST!$E:$E, TRUST!$D:$D,DEPARTMENTS!$B:$B, TRUST!$B:$B, J$13, TRUST!$B:$B, J$13) -> 3850 | K5: =SUMIFS(COLLECTION!$E:$E, COLLECTION!$D:$D,DEPARTMENTS!$B:$B, COLLECTION!$B:$B, K$13, COLLECTION!$B:$B, K$13) + SUMIFS(BANK!$E:$E, BANK!$D:$D,DEPARTMENTS!$B:$B, BANK!$B:$B, K$13, BANK!$B:$B, K$13) + SUMIFS(TRUST!$E:$E, TRUST!$D:$D,DEPARTMENTS!$B:$B, TRUST!$B:$B, K$13, TRUST!$B:$B, K$13) -> 3815 | L5: =SUMIFS(COLLECTION!$E:$E, COLLECTION!$D:$D,DEPARTMENTS!$B:$B, COLLECTION!$B:$B, L$13, COLLECTION!$B:$B, L$13) + SUMIFS(BANK!$E:$E, BANK!$D:$D,DEPARTMENTS!$B:$B, BANK!$B:$B, L$13, BANK!$B:$B, L$13) + SUMIFS(TRUST!$E:$E, TRUST!$D:$D,DEPARTMENTS!$B:$B, TRUST!$B:$B, L$13, TRUST!$B:$B, L$13) -> 5075 | M5: =SUMIFS(COLLECTION!$E:$E, COLLECTION!$D:$D,DEPARTMENTS!$B:$B, COLLECTION!$B:$B, M$13, COLLECTION!$B:$B, M$13) + SUMIFS(BANK!$E:$E, BANK!$D:$D,DEPARTMENTS!$B:$B, BANK!$B:$B, M$13, BANK!$B:$B, M$13) + SUMIFS(TRUST!$E:$E, TRUST!$D:$D,DEPARTMENTS!$B:$B, TRUST!$B:$B, M$13, TRUST!$B:$B, M$13) -> 1325 | N5: =SUMIFS(COLLECTION!$E:$E, COLLECTION!$D:$D,DEPARTMENTS!$B:$B, COLLECTION!$B:$B, N$13, COLLECTION!$B:$B, N$13) + SUMIFS(BANK!$E:$E, BANK!$D:$D,DEPARTMENTS!$B:$B, BANK!$B:$B, N$13, BANK!$B:$B, N$13) + SUMIFS(TRUST!$E:$E, TRUST!$D:$D,DEPARTMENTS!$B:$B, TRUST!$B:$B, N$13, TRUST!$B:$B, N$13) -> 0 | O5: =SUMIFS(COLLECTION!$E:$E, COLLECTION!$D:$D,DEPARTMENTS!$B:$B, COLLECTION!$B:$B, O$13, COLLECTION!$B:$B, O$13) + SUMIFS(BANK!$E:$E, BANK!$D:$D,DEPARTMENTS!$B:$B, BANK!$B:$B, O$13, BANK!$B:$B, O$13) + SUMIFS(TRUST!$E:$E, TRUST!$D:$D,DEPARTMENTS!$B:$B, TRUST!$B:$B, O$13, TRUST!$B:$B, O$13) -> 0 | ... S5: =SUMIFS(COLLECTION!$E:$E, COLLECTION!$D:$D,DEPARTMENTS!$B:$B, COLLECTION!$B:$B, S$13, COLLECTION!$B:$B, S$13) + SUMIFS(BANK!$E:$E, BANK!$D:$D,DEPARTMENTS!$B:$B, BANK!$B:$B, S$13, BANK!$B:$B, S$13) + SUMIFS(TRUST!$E:$E, TRUST!$D:$D,DEPARTMENTS!$B:$B, TRUST!$B:$B, S$13, TRUST!$B:$B, S$13) -> 0 | T5: =SUM(H5:S5) -> 39831 | AK5: =SUMIFS(COLLECTION!$E:$E, COLLECTION!$D:$D,DEPARTMENTS!$B:$B, COLLECTION!$B:$B, AK$12, COLLECTION!$C:$C, AK$13) + SUMIFS(BANK!$E:$E, BANK!$D:$D,DEPARTMENTS!$B:$B, BANK!$B:$B, AK$12, BANK!$C:$C, AK$13) + SUMIFS(TRUST!$E:$E, TRUST!$D:$D,DEPARTMENTS!$B:$B, TRUST!$B:$B, AK$12, TRUST!$C:$C, AK$13) -> 9591 | AL5: =SUMIFS(COLLECTION!$E:$E, COLLECTION!$D:$D,DEPARTMENTS!$B:$B, COLLECTION!$B:$B, AL$12, COLLECTION!$C:$C, AL$13) + SUMIFS(BANK!$E:$E, BANK!$D:$D,DEPARTMENTS!$B:$B, BANK!$B:$B, AL$12, BANK!$C:$C, AL$13) + SUMIFS(TRUST!$E:$E, TRUST!$D:$D,DEPARTMENTS!$B:$B, TRUST!$B:$B, AL$12, TRUST!$C:$C, AL$13) -> 4650 | AM5: =SUMIFS(COLLECTION!$E:$E, COLLECTION!$D:$D,DEPARTMENTS!$B:$B, COLLECTION!$B:$B, AM$12, COLLECTION!$C:$C, AM$13) + SUMIFS(BANK!$E:$E, BANK!$D:$D,DEPARTMENTS!$B:$B, BANK!$B:$B, AM$12, BANK!$C:$C, AM$13) + SUMIFS(TRUST!$E:$E, TRUST!$D:$D,DEPARTMENTS!$B:$B, TRUST!$B:$B, AM$12, TRUST!$C:$C, AM$13) -> 950 | AN5: =SUMIFS(COLLECTION!$E:$E, COLLECTION!$D:$D,DEPARTMENTS!$B:$B, COLLECTION!$B:$B, AN$12, COLLECTION!$C:$C, AN$13) + SUMIFS(BANK!$E:$E, BANK!$D:$D,DEPARTMENTS!$B:$B, BANK!$B:$B, AN$12, BANK!$C:$C, AN$13) + SUMIFS(TRUST!$E:$E, TRUST!$D:$D,DEPARTMENTS!$B:$B, TRUST!$B:$B, AN$12, TRUST!$C:$C, AN$13) -> 300 | AO5: =SUMIFS(COLLECTION!$E:$E, COLLECTION!$D:$D,DEPARTMENTS!$B:$B, COLLECTION!$B:$B, AO$12, COLLECTION!$C:$C, AO$13) + SUMIFS(BANK!$E:$E, BANK!$D:$D,DEPARTMENTS!$B:$B, BANK!$B:$B, AO$12, BANK!$C:$C, AO$13) + SUMIFS(TRUST!$E:$E, TRUST!$D:$D,DEPARTMENTS!$B:$B, TRUST!$B:$B, AO$12, TRUST!$C:$C, AO$13) -> 3650 | AP5: =SUMIFS(COLLECTION!$E:$E, COLLECTION!$D:$D,DEPARTMENTS!$B:$B, COLLECTION!$B:$B, AP$12, COLLECTION!$C:$C, AP$13) + SUMIFS(BANK!$E:$E, BANK!$D:$D,DEPARTMENTS!$B:$B, BANK!$B:$B, AP$12, BANK!$C:$C, AP$13) + SUMIFS(TRUST!$E:$E, TRUST!$D:$D,DEPARTMENTS!$B:$B, TRUST!$B:$B, AP$12, TRUST!$C:$C, AP$13) -> 2925 | AQ5: =SUMIFS(COLLECTION!$E:$E, COLLECTION!$D:$D,DEPARTMENTS!$B:$B, COLLECTION!$B:$B, AQ$12, COLLECTION!$C:$C, AQ$13) + SUMIFS(BANK!$E:$E, BANK!$D:$D,DEPARTMENTS!$B:$B, BANK!$B:$B, AQ$12, BANK!$C:$C, AQ$13) + SUMIFS(TRUST!$E:$E, TRUST!$D:$D,DEPARTMENTS!$B:$B, TRUST!$B:$B, AQ$12, TRUST!$C:$C, AQ$13) -> 350 | AR5: =SUMIFS(COLLECTION!$E:$E, COLLECTION!$D:$D,DEPARTMENTS!$B:$B, COLLECTION!$B:$B, AR$12, COLLECTION!$C:$C, AR$13) + SUMIFS(BANK!$E:$E, BANK!$D:$D,DEPARTMENTS!$B:$B, BANK!$B:$B, AR$12, BANK!$C:$C, AR$13) + SUMIFS(TRUST!$E:$E, TRUST!$D:$D,DEPARTMENTS!$B:$B, TRUST!$B:$B, AR$12, TRUST!$C:$C, AR$13) -> 2700 | ... BC5: =SUMIFS(COLLECTION!$E:$E, COLLECTION!$D:$D,DEPARTMENTS!$B:$B, COLLECTION!$B:$B, BC$12, COLLECTION!$C:$C, BC$13) + SUMIFS(BANK!$E:$E, BANK!$D:$D,DEPARTMENTS!$B:$B, BANK!$B:$B, BC$12, BANK!$C:$C, BC$13) + SUMIFS(TRUST!$E:$E, TRUST!$D:$D,DEPARTMENTS!$B:$B, TRUST!$B:$B, BC$12, TRUST!$C:$C, BC$13) -> 500 | BE5: =SUMIFS(COLLECTION!$E:$E, COLLECTION!$D:$D,DEPARTMENTS!$B:$B, COLLECTION!$B:$B, BE$12, COLLECTION!$C:$C, BE$13) + SUMIFS(BANK!$E:$E, BANK!$D:$D,DEPARTMENTS!$B:$B, BANK!$B:$B, BE$12, BANK!$C:$C, BE$13) + SUMIFS(TRUST!$E:$E, TRUST!$D:$D,DEPARTMENTS!$B:$B, TRUST!$B:$B, BE$12, TRUST!$C:$C, BE$13) -> 3275 | BF5: =SUMIFS(COLLECTION!$E:$E, COLLECTION!$D:$D,DEPARTMENTS!$B:$B, COLLECTION!$B:$B, BF$12, COLLECTION!$C:$C, BF$13) + SUMIFS(BANK!$E:$E, BANK!$D:$D,DEPARTMENTS!$B:$B, BANK!$B:$B, BF$12, BANK!$C:$C, BF$13) + SUMIFS(TRUST!$E:$E, TRUST!$D:$D,DEPARTMENTS!$B:$B, TRUST!$B:$B, BF$12, TRUST!$C:$C, BF$13) -> 1550 | BG5: =SUMIFS(COLLECTION!$E:$E, COLLECTION!$D:$D,DEPARTMENTS!$B:$B, COLLECTION!$B:$B, BG$12, COLLECTION!$C:$C, BG$13) + SUMIFS(BANK!$E:$E, BANK!$D:$D,DEPARTMENTS!$B:$B, BANK!$B:$B, BG$12, BANK!$C:$C, BG$13) + SUMIFS(TRUST!$E:$E, TRUST!$D:$D,DEPARTMENTS!$B:$B, TRUST!$B:$B, BG$12, TRUST!$C:$C, BG$13) -> 50 | BH5: =SUMIFS(COLLECTION!$E:$E, COLLECTION!$D:$D,DEPARTMENTS!$B:$B, COLLECTION!$B:$B, BH$12, COLLECTION!$C:$C, BH$13) + SUMIFS(BANK!$E:$E, BANK!$D:$D,DEPARTMENTS!$B:$B, BANK!$B:$B, BH$12, BANK!$C:$C, BH$13) + SUMIFS(TRUST!$E:$E, TRUST!$D:$D,DEPARTMENTS!$B:$B, TRUST!$B:$B, BH$12, TRUST!$C:$C, BH$13) -> 50 | BI5: =SUMIFS(COLLECTION!$E:$E, COLLECTION!$D:$D,DEPARTMENTS!$B:$B, COLLECTION!$B:$B, BI$12, COLLECTION!$C:$C, BI$13) + SUMIFS(BANK!$E:$E, BANK!$D:$D,DEPARTMENTS!$B:$B, BANK!$B:$B, BI$12, BANK!$C:$C, BI$13) + SUMIFS(TRUST!$E:$E, TRUST!$D:$D,DEPARTMENTS!$B:$B, TRUST!$B:$B, BI$12, TRUST!$C:$C, BI$13) -> 150 | BJ5: =SUMIFS(COLLECTION!$E:$E, COLLECTION!$D:$D,DEPARTMENTS!$B:$B, COLLECTION!$B:$B, BJ$12, COLLECTION!$C:$C, BJ$13) + SUMIFS(BANK!$E:$E, BANK!$D:$D,DEPARTMENTS!$B:$B, BANK!$B:$B, BJ$12, BANK!$C:$C, BJ$13) + SUMIFS(TRUST!$E:$E, TRUST!$D:$D,DEPARTMENTS!$B:$B, TRUST!$B:$B, BJ$12, TRUST!$C:$C, BJ$13) -> 1325 | BK5: =SUMIFS(COLLECTION!$E:$E, COLLECTION!$D:$D,DEPARTMENTS!$B:$B, COLLECTION!$B:$B, BK$12, COLLECTION!$C:$C, BK$13) + SUMIFS(BANK!$E:$E, BANK!$D:$D,DEPARTMENTS!$B:$B, BANK!$B:$B, BK$12, BANK!$C:$C, BK$13) + SUMIFS(TRUST!$E:$E, TRUST!$D:$D,DEPARTMENTS!$B:$B, TRUST!$B:$B, BK$12, TRUST!$C:$C, BK$13) -> 0 | BL5: =SUMIFS(COLLECTION!$E:$E, COLLECTION!$D:$D,DEPARTMENTS!$B:$B, COLLECTION!$B:$B, BL$12, COLLECTION!$C:$C, BL$13) + SUMIFS(BANK!$E:$E, BANK!$D:$D,DEPARTMENTS!$B:$B, BANK!$B:$B, BL$12, BANK!$C:$C, BL$13) + SUMIFS(TRUST!$E:$E, TRUST!$D:$D,DEPARTMENTS!$B:$B, TRUST!$B:$B, BL$12, TRUST!$C:$C, BL$13) -> 0 | ... CQ5: =SUMIFS(COLLECTION!$E:$E, COLLECTION!$D:$D,DEPARTMENTS!$B:$B, COLLECTION!$B:$B, CQ$12, COLLECTION!$C:$C, CQ$13) + SUMIFS(BANK!$E:$E, BANK!$D:$D,DEPARTMENTS!$B:$B, BANK!$B:$B, CQ$12, BANK!$C:$C, CQ$13) + SUMIFS(TRUST!$E:$E, TRUST!$D:$D,DEPARTMENTS!$B:$B, TRUST!$B:$B, CQ$12, TRUST!$C:$C, CQ$13) -> 0 | CR5: =SUM(AK5:CQ5) -> 39831
B6: LOCAL CHURCH BUDGET | C6: 0 | D6: =SUMIF(COLLECTION!D:D,DEPARTMENTS!B:B,COLLECTION!E:E)+SUMIF(BANK!D:D,DEPARTMENTS!B:B,BANK!E:E)+SUMIF(TRUST!D:D,DEPARTMENTS!B:B,TRUST!E:E) -> 201802 | H6: =SUMIFS(COLLECTION!$E:$E, COLLECTION!$D:$D,DEPARTMENTS!$B:$B, COLLECTION!$B:$B, H$13, COLLECTION!$B:$B, H$13) + SUMIFS(BANK!$E:$E, BANK!$D:$D,DEPARTMENTS!$B:$B, BANK!$B:$B, H$13, BANK!$B:$B, H$13) + SUMIFS(TRUST!$E:$E, TRUST!$D:$D,DEPARTMENTS!$B:$B, TRUST!$B:$B, H$13, TRUST!$B:$B, H$13) -> 54062 | I6: =SUMIFS(COLLECTION!$E:$E, COLLECTION!$D:$D,DEPARTMENTS!$B:$B, COLLECTION!$B:$B, I$13, COLLECTION!$B:$B, I$13) + SUMIFS(BANK!$E:$E, BANK!$D:$D,DEPARTMENTS!$B:$B, BANK!$B:$B, I$13, BANK!$B:$B, I$13) + SUMIFS(TRUST!$E:$E, TRUST!$D:$D,DEPARTMENTS!$B:$B, TRUST!$B:$B, I$13, TRUST!$B:$B, I$13) -> 30890 | J6: =SUMIFS(COLLECTION!$E:$E, COLLECTION!$D:$D,DEPARTMENTS!$B:$B, COLLECTION!$B:$B, J$13, COLLECTION!$B:$B, J$13) + SUMIFS(BANK!$E:$E, BANK!$D:$D,DEPARTMENTS!$B:$B, BANK!$B:$B, J$13, BANK!$B:$B, J$13) + SUMIFS(TRUST!$E:$E, TRUST!$D:$D,DEPARTMENTS!$B:$B, TRUST!$B:$B, J$13, TRUST!$B:$B, J$13) -> 37945 | K6: =SUMIFS(COLLECTION!$E:$E, COLLECTION!$D:$D,DEPARTMENTS!$B:$B, COLLECTION!$B:$B, K$13, COLLECTION!$B:$B, K$13) + SUMIFS(BANK!$E:$E, BANK!$D:$D,DEPARTMENTS!$B:$B, BANK!$B:$B, K$13, BANK!$B:$B, K$13) + SUMIFS(TRUST!$E:$E, TRUST!$D:$D,DEPARTMENTS!$B:$B, TRUST!$B:$B, K$13, TRUST!$B:$B, K$13) -> 23560 | L6: =SUMIFS(COLLECTION!$E:$E, COLLECTION!$D:$D,DEPARTMENTS!$B:$B, COLLECTION!$B:$B, L$13, COLLECTION!$B:$B, L$13) + SUMIFS(BANK!$E:$E, BANK!$D:$D,DEPARTMENTS!$B:$B, BANK!$B:$B, L$13, BANK!$B:$B, L$13) + SUMIFS(TRUST!$E:$E, TRUST!$D:$D,DEPARTMENTS!$B:$B, TRUST!$B:$B, L$13, TRUST!$B:$B, L$13) -> 45495 | M6: =SUMIFS(COLLECTION!$E:$E, COLLECTION!$D:$D,DEPARTMENTS!$B:$B, COLLECTION!$B:$B, M$13, COLLECTION!$B:$B, M$13) + SUMIFS(BANK!$E:$E, BANK!$D:$D,DEPARTMENTS!$B:$B, BANK!$B:$B, M$13, BANK!$B:$B, M$13) + SUMIFS(TRUST!$E:$E, TRUST!$D:$D,DEPARTMENTS!$B:$B, TRUST!$B:$B, M$13, TRUST!$B:$B, M$13) -> 9850 | N6: =SUMIFS(COLLECTION!$E:$E, COLLECTION!$D:$D,DEPARTMENTS!$B:$B, COLLECTION!$B:$B, N$13, COLLECTION!$B:$B, N$13) + SUMIFS(BANK!$E:$E, BANK!$D:$D,DEPARTMENTS!$B:$B, BANK!$B:$B, N$13, BANK!$B:$B, N$13) + SUMIFS(TRUST!$E:$E, TRUST!$D:$D,DEPARTMENTS!$B:$B, TRUST!$B:$B, N$13, TRUST!$B:$B, N$13) -> 0 | O6: =SUMIFS(COLLECTION!$E:$E, COLLECTION!$D:$D,DEPARTMENTS!$B:$B, COLLECTION!$B:$B, O$13, COLLECTION!$B:$B, O$13) + SUMIFS(BANK!$E:$E, BANK!$D:$D,DEPARTMENTS!$B:$B, BANK!$B:$B, O$13, BANK!$B:$B, O$13) + SUMIFS(TRUST!$E:$E, TRUST!$D:$D,DEPARTMENTS!$B:$B, TRUST!$B:$B, O$13, TRUST!$B:$B, O$13) -> 0 | ... S6: =SUMIFS(COLLECTION!$E:$E, COLLECTION!$D:$D,DEPARTMENTS!$B:$B, COLLECTION!$B:$B, S$13, COLLECTION!$B:$B, S$13) + SUMIFS(BANK!$E:$E, BANK!$D:$D,DEPARTMENTS!$B:$B, BANK!$B:$B, S$13, BANK!$B:$B, S$13) + SUMIFS(TRUST!$E:$E, TRUST!$D:$D,DEPARTMENTS!$B:$B, TRUST!$B:$B, S$13, TRUST!$B:$B, S$13) -> 0 | T6: =SUM(H6:S6) -> 201802 | AK6: =SUMIFS(COLLECTION!$E:$E, COLLECTION!$D:$D,DEPARTMENTS!$B:$B, COLLECTION!$B:$B, AK$12, COLLECTION!$C:$C, AK$13) + SUMIFS(BANK!$E:$E, BANK!$D:$D,DEPARTMENTS!$B:$B, BANK!$B:$B, AK$12, BANK!$C:$C, AK$13) + SUMIFS(TRUST!$E:$E, TRUST!$D:$D,DEPARTMENTS!$B:$B, TRUST!$B:$B, AK$12, TRUST!$C:$C, AK$13) -> 8655 | AL6: =SUMIFS(COLLECTION!$E:$E, COLLECTION!$D:$D,DEPARTMENTS!$B:$B, COLLECTION!$B:$B, AL$12, COLLECTION!$C:$C, AL$13) + SUMIFS(BANK!$E:$E, BANK!$D:$D,DEPARTMENTS!$B:$B, BANK!$B:$B, AL$12, BANK!$C:$C, AL$13) + SUMIFS(TRUST!$E:$E, TRUST!$D:$D,DEPARTMENTS!$B:$B, TRUST!$B:$B, AL$12, TRUST!$C:$C, AL$13) -> 12750 | AM6: =SUMIFS(COLLECTION!$E:$E, COLLECTION!$D:$D,DEPARTMENTS!$B:$B, COLLECTION!$B:$B, AM$12, COLLECTION!$C:$C, AM$13) + SUMIFS(BANK!$E:$E, BANK!$D:$D,DEPARTMENTS!$B:$B, BANK!$B:$B, AM$12, BANK!$C:$C, AM$13) + SUMIFS(TRUST!$E:$E, TRUST!$D:$D,DEPARTMENTS!$B:$B, TRUST!$B:$B, AM$12, TRUST!$C:$C, AM$13) -> 5175 | AN6: =SUMIFS(COLLECTION!$E:$E, COLLECTION!$D:$D,DEPARTMENTS!$B:$B, COLLECTION!$B:$B, AN$12, COLLECTION!$C:$C, AN$13) + SUMIFS(BANK!$E:$E, BANK!$D:$D,DEPARTMENTS!$B:$B, BANK!$B:$B, AN$12, BANK!$C:$C, AN$13) + SUMIFS(TRUST!$E:$E, TRUST!$D:$D,DEPARTMENTS!$B:$B, TRUST!$B:$B, AN$12, TRUST!$C:$C, AN$13) -> 7735 | AO6: =SUMIFS(COLLECTION!$E:$E, COLLECTION!$D:$D,DEPARTMENTS!$B:$B, COLLECTION!$B:$B, AO$12, COLLECTION!$C:$C, AO$13) + SUMIFS(BANK!$E:$E, BANK!$D:$D,DEPARTMENTS!$B:$B, BANK!$B:$B, AO$12, BANK!$C:$C, AO$13) + SUMIFS(TRUST!$E:$E, TRUST!$D:$D,DEPARTMENTS!$B:$B, TRUST!$B:$B, AO$12, TRUST!$C:$C, AO$13) -> 19747 | AP6: =SUMIFS(COLLECTION!$E:$E, COLLECTION!$D:$D,DEPARTMENTS!$B:$B, COLLECTION!$B:$B, AP$12, COLLECTION!$C:$C, AP$13) + SUMIFS(BANK!$E:$E, BANK!$D:$D,DEPARTMENTS!$B:$B, BANK!$B:$B, AP$12, BANK!$C:$C, AP$13) + SUMIFS(TRUST!$E:$E, TRUST!$D:$D,DEPARTMENTS!$B:$B, TRUST!$B:$B, AP$12, TRUST!$C:$C, AP$13) -> 4570 | AQ6: =SUMIFS(COLLECTION!$E:$E, COLLECTION!$D:$D,DEPARTMENTS!$B:$B, COLLECTION!$B:$B, AQ$12, COLLECTION!$C:$C, AQ$13) + SUMIFS(BANK!$E:$E, BANK!$D:$D,DEPARTMENTS!$B:$B, BANK!$B:$B, AQ$12, BANK!$C:$C, AQ$13) + SUMIFS(TRUST!$E:$E, TRUST!$D:$D,DEPARTMENTS!$B:$B, TRUST!$B:$B, AQ$12, TRUST!$C:$C, AQ$13) -> 6650 | AR6: =SUMIFS(COLLECTION!$E:$E, COLLECTION!$D:$D,DEPARTMENTS!$B:$B, COLLECTION!$B:$B, AR$12, COLLECTION!$C:$C, AR$13) + SUMIFS(BANK!$E:$E, BANK!$D:$D,DEPARTMENTS!$B:$B, BANK!$B:$B, AR$12, BANK!$C:$C, AR$13) + SUMIFS(TRUST!$E:$E, TRUST!$D:$D,DEPARTMENTS!$B:$B, TRUST!$B:$B, AR$12, TRUST!$C:$C, AR$13) -> 13870 | ... BC6: =SUMIFS(COLLECTION!$E:$E, COLLECTION!$D:$D,DEPARTMENTS!$B:$B, COLLECTION!$B:$B, BC$12, COLLECTION!$C:$C, BC$13) + SUMIFS(BANK!$E:$E, BANK!$D:$D,DEPARTMENTS!$B:$B, BANK!$B:$B, BC$12, BANK!$C:$C, BC$13) + SUMIFS(TRUST!$E:$E, TRUST!$D:$D,DEPARTMENTS!$B:$B, TRUST!$B:$B, BC$12, TRUST!$C:$C, BC$13) -> 7350 | BE6: =SUMIFS(COLLECTION!$E:$E, COLLECTION!$D:$D,DEPARTMENTS!$B:$B, COLLECTION!$B:$B, BE$12, COLLECTION!$C:$C, BE$13) + SUMIFS(BANK!$E:$E, BANK!$D:$D,DEPARTMENTS!$B:$B, BANK!$B:$B, BE$12, BANK!$C:$C, BE$13) + SUMIFS(TRUST!$E:$E, TRUST!$D:$D,DEPARTMENTS!$B:$B, TRUST!$B:$B, BE$12, TRUST!$C:$C, BE$13) -> 6930 | BF6: =SUMIFS(COLLECTION!$E:$E, COLLECTION!$D:$D,DEPARTMENTS!$B:$B, COLLECTION!$B:$B, BF$12, COLLECTION!$C:$C, BF$13) + SUMIFS(BANK!$E:$E, BANK!$D:$D,DEPARTMENTS!$B:$B, BANK!$B:$B, BF$12, BANK!$C:$C, BF$13) + SUMIFS(TRUST!$E:$E, TRUST!$D:$D,DEPARTMENTS!$B:$B, TRUST!$B:$B, BF$12, TRUST!$C:$C, BF$13) -> 28770 | BG6: =SUMIFS(COLLECTION!$E:$E, COLLECTION!$D:$D,DEPARTMENTS!$B:$B, COLLECTION!$B:$B, BG$12, COLLECTION!$C:$C, BG$13) + SUMIFS(BANK!$E:$E, BANK!$D:$D,DEPARTMENTS!$B:$B, BANK!$B:$B, BG$12, BANK!$C:$C, BG$13) + SUMIFS(TRUST!$E:$E, TRUST!$D:$D,DEPARTMENTS!$B:$B, TRUST!$B:$B, BG$12, TRUST!$C:$C, BG$13) -> 4320 | BH6: =SUMIFS(COLLECTION!$E:$E, COLLECTION!$D:$D,DEPARTMENTS!$B:$B, COLLECTION!$B:$B, BH$12, COLLECTION!$C:$C, BH$13) + SUMIFS(BANK!$E:$E, BANK!$D:$D,DEPARTMENTS!$B:$B, BANK!$B:$B, BH$12, BANK!$C:$C, BH$13) + SUMIFS(TRUST!$E:$E, TRUST!$D:$D,DEPARTMENTS!$B:$B, TRUST!$B:$B, BH$12, TRUST!$C:$C, BH$13) -> 3030 | BI6: =SUMIFS(COLLECTION!$E:$E, COLLECTION!$D:$D,DEPARTMENTS!$B:$B, COLLECTION!$B:$B, BI$12, COLLECTION!$C:$C, BI$13) + SUMIFS(BANK!$E:$E, BANK!$D:$D,DEPARTMENTS!$B:$B, BANK!$B:$B, BI$12, BANK!$C:$C, BI$13) + SUMIFS(TRUST!$E:$E, TRUST!$D:$D,DEPARTMENTS!$B:$B, TRUST!$B:$B, BI$12, TRUST!$C:$C, BI$13) -> 2445 | BJ6: =SUMIFS(COLLECTION!$E:$E, COLLECTION!$D:$D,DEPARTMENTS!$B:$B, COLLECTION!$B:$B, BJ$12, COLLECTION!$C:$C, BJ$13) + SUMIFS(BANK!$E:$E, BANK!$D:$D,DEPARTMENTS!$B:$B, BANK!$B:$B, BJ$12, BANK!$C:$C, BJ$13) + SUMIFS(TRUST!$E:$E, TRUST!$D:$D,DEPARTMENTS!$B:$B, TRUST!$B:$B, BJ$12, TRUST!$C:$C, BJ$13) -> 9850 | BK6: =SUMIFS(COLLECTION!$E:$E, COLLECTION!$D:$D,DEPARTMENTS!$B:$B, COLLECTION!$B:$B, BK$12, COLLECTION!$C:$C, BK$13) + SUMIFS(BANK!$E:$E, BANK!$D:$D,DEPARTMENTS!$B:$B, BANK!$B:$B, BK$12, BANK!$C:$C, BK$13) + SUMIFS(TRUST!$E:$E, TRUST!$D:$D,DEPARTMENTS!$B:$B, TRUST!$B:$B, BK$12, TRUST!$C:$C, BK$13) -> 0 | BL6: =SUMIFS(COLLECTION!$E:$E, COLLECTION!$D:$D,DEPARTMENTS!$B:$B, COLLECTION!$B:$B, BL$12, COLLECTION!$C:$C, BL$13) + SUMIFS(BANK!$E:$E, BANK!$D:$D,DEPARTMENTS!$B:$B, BANK!$B:$B, BL$12, BANK!$C:$C, BL$13) + SUMIFS(TRUST!$E:$E, TRUST!$D:$D,DEPARTMENTS!$B:$B, TRUST!$B:$B, BL$12, TRUST!$C:$C, BL$13) -> 0 | ... CQ6: =SUMIFS(COLLECTION!$E:$E, COLLECTION!$D:$D,DEPARTMENTS!$B:$B, COLLECTION!$B:$B, CQ$12, COLLECTION!$C:$C, CQ$13) + SUMIFS(BANK!$E:$E, BANK!$D:$D,DEPARTMENTS!$B:$B, BANK!$B:$B, CQ$12, BANK!$C:$C, CQ$13) + SUMIFS(TRUST!$E:$E, TRUST!$D:$D,DEPARTMENTS!$B:$B, TRUST!$B:$B, CQ$12, TRUST!$C:$C, CQ$13) -> 0 | CR6: =SUM(AK6:CQ6) -> 201802
B7: ENVELOPES | C7: 0 | D7: =SUMIF(COLLECTION!D:D,DEPARTMENTS!B:B,COLLECTION!E:E)+SUMIF(BANK!D:D,DEPARTMENTS!B:B,BANK!E:E)+SUMIF(TRUST!D:D,DEPARTMENTS!B:B,TRUST!E:E)-D69 -> 2190 | E7: =(ABS(D7))/DASHBOARD!B7 -> 0.00023235845 | H7: =SUMIFS(COLLECTION!$E:$E, COLLECTION!$D:$D,DEPARTMENTS!$B:$B, COLLECTION!$B:$B, H$13, COLLECTION!$B:$B, H$13) + SUMIFS(BANK!$E:$E, BANK!$D:$D,DEPARTMENTS!$B:$B, BANK!$B:$B, H$13, BANK!$B:$B, H$13) + SUMIFS(TRUST!$E:$E, TRUST!$D:$D,DEPARTMENTS!$B:$B, TRUST!$B:$B, H$13, TRUST!$B:$B, H$13)-H69 -> 3947 | I7: =SUMIFS(COLLECTION!$E:$E, COLLECTION!$D:$D,DEPARTMENTS!$B:$B, COLLECTION!$B:$B, I$13, COLLECTION!$B:$B, I$13) + SUMIFS(BANK!$E:$E, BANK!$D:$D,DEPARTMENTS!$B:$B, BANK!$B:$B, I$13, BANK!$B:$B, I$13) + SUMIFS(TRUST!$E:$E, TRUST!$D:$D,DEPARTMENTS!$B:$B, TRUST!$B:$B, I$13, TRUST!$B:$B, I$13)-I69 -> 21 | J7: =SUMIFS(COLLECTION!$E:$E, COLLECTION!$D:$D,DEPARTMENTS!$B:$B, COLLECTION!$B:$B, J$13, COLLECTION!$B:$B, J$13) + SUMIFS(BANK!$E:$E, BANK!$D:$D,DEPARTMENTS!$B:$B, BANK!$B:$B, J$13, BANK!$B:$B, J$13) + SUMIFS(TRUST!$E:$E, TRUST!$D:$D,DEPARTMENTS!$B:$B, TRUST!$B:$B, J$13, TRUST!$B:$B, J$13)-J69 -> 14538 | K7: =SUMIFS(COLLECTION!$E:$E, COLLECTION!$D:$D,DEPARTMENTS!$B:$B, COLLECTION!$B:$B, K$13, COLLECTION!$B:$B, K$13) + SUMIFS(BANK!$E:$E, BANK!$D:$D,DEPARTMENTS!$B:$B, BANK!$B:$B, K$13, BANK!$B:$B, K$13) + SUMIFS(TRUST!$E:$E, TRUST!$D:$D,DEPARTMENTS!$B:$B, TRUST!$B:$B, K$13, TRUST!$B:$B, K$13)-K69 -> 19401 | L7: =SUMIFS(COLLECTION!$E:$E, COLLECTION!$D:$D,DEPARTMENTS!$B:$B, COLLECTION!$B:$B, L$13, COLLECTION!$B:$B, L$13) + SUMIFS(BANK!$E:$E, BANK!$D:$D,DEPARTMENTS!$B:$B, BANK!$B:$B, L$13, BANK!$B:$B, L$13) + SUMIFS(TRUST!$E:$E, TRUST!$D:$D,DEPARTMENTS!$B:$B, TRUST!$B:$B, L$13, TRUST!$B:$B, L$13)-L69 -> -4467 | M7: =SUMIFS(COLLECTION!$E:$E, COLLECTION!$D:$D,DEPARTMENTS!$B:$B, COLLECTION!$B:$B, M$13, COLLECTION!$B:$B, M$13) + SUMIFS(BANK!$E:$E, BANK!$D:$D,DEPARTMENTS!$B:$B, BANK!$B:$B, M$13, BANK!$B:$B, M$13) + SUMIFS(TRUST!$E:$E, TRUST!$D:$D,DEPARTMENTS!$B:$B, TRUST!$B:$B, M$13, TRUST!$B:$B, M$13)-M69 -> -31250 | N7: =SUMIFS(COLLECTION!$E:$E, COLLECTION!$D:$D,DEPARTMENTS!$B:$B, COLLECTION!$B:$B, N$13, COLLECTION!$B:$B, N$13) + SUMIFS(BANK!$E:$E, BANK!$D:$D,DEPARTMENTS!$B:$B, BANK!$B:$B, N$13, BANK!$B:$B, N$13) + SUMIFS(TRUST!$E:$E, TRUST!$D:$D,DEPARTMENTS!$B:$B, TRUST!$B:$B, N$13, TRUST!$B:$B, N$13)-N69 -> 0 | O7: =SUMIFS(COLLECTION!$E:$E, COLLECTION!$D:$D,DEPARTMENTS!$B:$B, COLLECTION!$B:$B, O$13, COLLECTION!$B:$B, O$13) + SUMIFS(BANK!$E:$E, BANK!$D:$D,DEPARTMENTS!$B:$B, BANK!$B:$B, O$13, BANK!$B:$B, O$13) + SUMIFS(TRUST!$E:$E, TRUST!$D:$D,DEPARTMENTS!$B:$B, TRUST!$B:$B, O$13, TRUST!$B:$B, O$13)-O69 -> 0 | ... S7: =SUMIFS(COLLECTION!$E:$E, COLLECTION!$D:$D,DEPARTMENTS!$B:$B, COLLECTION!$B:$B, S$13, COLLECTION!$B:$B, S$13) + SUMIFS(BANK!$E:$E, BANK!$D:$D,DEPARTMENTS!$B:$B, BANK!$B:$B, S$13, BANK!$B:$B, S$13) + SUMIFS(TRUST!$E:$E, TRUST!$D:$D,DEPARTMENTS!$B:$B, TRUST!$B:$B, S$13, TRUST!$B:$B, S$13)-S69 -> 0 | T7: =SUM(H7:S7) -> 2190 | AK7: =SUMIFS(COLLECTION!$E:$E, COLLECTION!$D:$D,DEPARTMENTS!$B:$B, COLLECTION!$B:$B, AK$12, COLLECTION!$C:$C, AK$13) + SUMIFS(BANK!$E:$E, BANK!$D:$D,DEPARTMENTS!$B:$B, BANK!$B:$B, AK$12, BANK!$C:$C, AK$13) + SUMIFS(TRUST!$E:$E, TRUST!$D:$D,DEPARTMENTS!$B:$B, TRUST!$B:$B, AK$12, TRUST!$C:$C, AK$13)-AK69 -> 11558 | AL7: =SUMIFS(COLLECTION!$E:$E, COLLECTION!$D:$D,DEPARTMENTS!$B:$B, COLLECTION!$B:$B, AL$12, COLLECTION!$C:$C, AL$13) + SUMIFS(BANK!$E:$E, BANK!$D:$D,DEPARTMENTS!$B:$B, BANK!$B:$B, AL$12, BANK!$C:$C, AL$13) + SUMIFS(TRUST!$E:$E, TRUST!$D:$D,DEPARTMENTS!$B:$B, TRUST!$B:$B, AL$12, TRUST!$C:$C, AL$13)-AL69 -> -11501.5 | AM7: =SUMIFS(COLLECTION!$E:$E, COLLECTION!$D:$D,DEPARTMENTS!$B:$B, COLLECTION!$B:$B, AM$12, COLLECTION!$C:$C, AM$13) + SUMIFS(BANK!$E:$E, BANK!$D:$D,DEPARTMENTS!$B:$B, BANK!$B:$B, AM$12, BANK!$C:$C, AM$13) + SUMIFS(TRUST!$E:$E, TRUST!$D:$D,DEPARTMENTS!$B:$B, TRUST!$B:$B, AM$12, TRUST!$C:$C, AM$13)-AM69 -> 15739 | AN7: =SUMIFS(COLLECTION!$E:$E, COLLECTION!$D:$D,DEPARTMENTS!$B:$B, COLLECTION!$B:$B, AN$12, COLLECTION!$C:$C, AN$13) + SUMIFS(BANK!$E:$E, BANK!$D:$D,DEPARTMENTS!$B:$B, BANK!$B:$B, AN$12, BANK!$C:$C, AN$13) + SUMIFS(TRUST!$E:$E, TRUST!$D:$D,DEPARTMENTS!$B:$B, TRUST!$B:$B, AN$12, TRUST!$C:$C, AN$13)-AN69 -> -19577.5 | AO7: =SUMIFS(COLLECTION!$E:$E, COLLECTION!$D:$D,DEPARTMENTS!$B:$B, COLLECTION!$B:$B, AO$12, COLLECTION!$C:$C, AO$13) + SUMIFS(BANK!$E:$E, BANK!$D:$D,DEPARTMENTS!$B:$B, BANK!$B:$B, AO$12, BANK!$C:$C, AO$13) + SUMIFS(TRUST!$E:$E, TRUST!$D:$D,DEPARTMENTS!$B:$B, TRUST!$B:$B, AO$12, TRUST!$C:$C, AO$13)-AO69 -> 7729 | AP7: =SUMIFS(COLLECTION!$E:$E, COLLECTION!$D:$D,DEPARTMENTS!$B:$B, COLLECTION!$B:$B, AP$12, COLLECTION!$C:$C, AP$13) + SUMIFS(BANK!$E:$E, BANK!$D:$D,DEPARTMENTS!$B:$B, BANK!$B:$B, AP$12, BANK!$C:$C, AP$13) + SUMIFS(TRUST!$E:$E, TRUST!$D:$D,DEPARTMENTS!$B:$B, TRUST!$B:$B, AP$12, TRUST!$C:$C, AP$13)-AP69 -> 145 | AQ7: =SUMIFS(COLLECTION!$E:$E, COLLECTION!$D:$D,DEPARTMENTS!$B:$B, COLLECTION!$B:$B, AQ$12, COLLECTION!$C:$C, AQ$13) + SUMIFS(BANK!$E:$E, BANK!$D:$D,DEPARTMENTS!$B:$B, BANK!$B:$B, AQ$12, BANK!$C:$C, AQ$13) + SUMIFS(TRUST!$E:$E, TRUST!$D:$D,DEPARTMENTS!$B:$B, TRUST!$B:$B, AQ$12, TRUST!$C:$C, AQ$13)-AQ69 -> -580 | AR7: =SUMIFS(COLLECTION!$E:$E, COLLECTION!$D:$D,DEPARTMENTS!$B:$B, COLLECTION!$B:$B, AR$12, COLLECTION!$C:$C, AR$13) + SUMIFS(BANK!$E:$E, BANK!$D:$D,DEPARTMENTS!$B:$B, BANK!$B:$B, AR$12, BANK!$C:$C, AR$13) + SUMIFS(TRUST!$E:$E, TRUST!$D:$D,DEPARTMENTS!$B:$B, TRUST!$B:$B, AR$12, TRUST!$C:$C, AR$13)-AR69 -> 3700 | ... BC7: =SUMIFS(COLLECTION!$E:$E, COLLECTION!$D:$D,DEPARTMENTS!$B:$B, COLLECTION!$B:$B, BC$12, COLLECTION!$C:$C, BC$13) + SUMIFS(BANK!$E:$E, BANK!$D:$D,DEPARTMENTS!$B:$B, BANK!$B:$B, BC$12, BANK!$C:$C, BC$13) + SUMIFS(TRUST!$E:$E, TRUST!$D:$D,DEPARTMENTS!$B:$B, TRUST!$B:$B, BC$12, TRUST!$C:$C, BC$13)-BC69 -> 501 | BE7: =SUMIFS(COLLECTION!$E:$E, COLLECTION!$D:$D,DEPARTMENTS!$B:$B, COLLECTION!$B:$B, BE$12, COLLECTION!$C:$C, BE$13) + SUMIFS(BANK!$E:$E, BANK!$D:$D,DEPARTMENTS!$B:$B, BANK!$B:$B, BE$12, BANK!$C:$C, BE$13) + SUMIFS(TRUST!$E:$E, TRUST!$D:$D,DEPARTMENTS!$B:$B, TRUST!$B:$B, BE$12, TRUST!$C:$C, BE$13)-BE69 -> -29475 | BF7: =SUMIFS(COLLECTION!$E:$E, COLLECTION!$D:$D,DEPARTMENTS!$B:$B, COLLECTION!$B:$B, BF$12, COLLECTION!$C:$C, BF$13) + SUMIFS(BANK!$E:$E, BANK!$D:$D,DEPARTMENTS!$B:$B, BANK!$B:$B, BF$12, BANK!$C:$C, BF$13) + SUMIFS(TRUST!$E:$E, TRUST!$D:$D,DEPARTMENTS!$B:$B, TRUST!$B:$B, BF$12, TRUST!$C:$C, BF$13)-BF69 -> -7235 | BG7: =SUMIFS(COLLECTION!$E:$E, COLLECTION!$D:$D,DEPARTMENTS!$B:$B, COLLECTION!$B:$B, BG$12, COLLECTION!$C:$C, BG$13) + SUMIFS(BANK!$E:$E, BANK!$D:$D,DEPARTMENTS!$B:$B, BANK!$B:$B, BG$12, BANK!$C:$C, BG$13) + SUMIFS(TRUST!$E:$E, TRUST!$D:$D,DEPARTMENTS!$B:$B, TRUST!$B:$B, BG$12, TRUST!$C:$C, BG$13)-BG69 -> -10780 | BH7: =SUMIFS(COLLECTION!$E:$E, COLLECTION!$D:$D,DEPARTMENTS!$B:$B, COLLECTION!$B:$B, BH$12, COLLECTION!$C:$C, BH$13) + SUMIFS(BANK!$E:$E, BANK!$D:$D,DEPARTMENTS!$B:$B, BANK!$B:$B, BH$12, BANK!$C:$C, BH$13) + SUMIFS(TRUST!$E:$E, TRUST!$D:$D,DEPARTMENTS!$B:$B, TRUST!$B:$B, BH$12, TRUST!$C:$C, BH$13)-BH69 -> 10005 | BI7: =SUMIFS(COLLECTION!$E:$E, COLLECTION!$D:$D,DEPARTMENTS!$B:$B, COLLECTION!$B:$B, BI$12, COLLECTION!$C:$C, BI$13) + SUMIFS(BANK!$E:$E, BANK!$D:$D,DEPARTMENTS!$B:$B, BANK!$B:$B, BI$12, BANK!$C:$C, BI$13) + SUMIFS(TRUST!$E:$E, TRUST!$D:$D,DEPARTMENTS!$B:$B, TRUST!$B:$B, BI$12, TRUST!$C:$C, BI$13)-BI69 -> 33018 | BJ7: =SUMIFS(COLLECTION!$E:$E, COLLECTION!$D:$D,DEPARTMENTS!$B:$B, COLLECTION!$B:$B, BJ$12, COLLECTION!$C:$C, BJ$13) + SUMIFS(BANK!$E:$E, BANK!$D:$D,DEPARTMENTS!$B:$B, BANK!$B:$B, BJ$12, BANK!$C:$C, BJ$13) + SUMIFS(TRUST!$E:$E, TRUST!$D:$D,DEPARTMENTS!$B:$B, TRUST!$B:$B, BJ$12, TRUST!$C:$C, BJ$13)-BJ69 -> -19442.5 | BK7: =SUMIFS(COLLECTION!$E:$E, COLLECTION!$D:$D,DEPARTMENTS!$B:$B, COLLECTION!$B:$B, BK$12, COLLECTION!$C:$C, BK$13) + SUMIFS(BANK!$E:$E, BANK!$D:$D,DEPARTMENTS!$B:$B, BANK!$B:$B, BK$12, BANK!$C:$C, BK$13) + SUMIFS(TRUST!$E:$E, TRUST!$D:$D,DEPARTMENTS!$B:$B, TRUST!$B:$B, BK$12, TRUST!$C:$C, BK$13)-BK69 -> 0 | BL7: =SUMIFS(COLLECTION!$E:$E, COLLECTION!$D:$D,DEPARTMENTS!$B:$B, COLLECTION!$B:$B, BL$12, COLLECTION!$C:$C, BL$13) + SUMIFS(BANK!$E:$E, BANK!$D:$D,DEPARTMENTS!$B:$B, BANK!$B:$B, BL$12, BANK!$C:$C, BL$13) + SUMIFS(TRUST!$E:$E, TRUST!$D:$D,DEPARTMENTS!$B:$B, TRUST!$B:$B, BL$12, TRUST!$C:$C, BL$13)-BL69 -> 0 | ... CQ7: =SUMIFS(COLLECTION!$E:$E, COLLECTION!$D:$D,DEPARTMENTS!$B:$B, COLLECTION!$B:$B, CQ$12, COLLECTION!$C:$C, CQ$13) + SUMIFS(BANK!$E:$E, BANK!$D:$D,DEPARTMENTS!$B:$B, BANK!$B:$B, CQ$12, BANK!$C:$C, CQ$13) + SUMIFS(TRUST!$E:$E, TRUST!$D:$D,DEPARTMENTS!$B:$B, TRUST!$B:$B, CQ$12, TRUST!$C:$C, CQ$13)-CQ69 -> 0 | CR7: =SUM(AK7:CQ7) -> -15322.5
