Workbook

Sheet OFFERING SUMMARY
C2: SDA CHURCH KAHAWA WENDANI
C3: COLLECTION SUMMARY FROM 7 FEB 2026 TO 28TH FEB 2026
D4: 46060 | E4: =D4+7 -> 46067 | F4: =E4+7 -> 46074 | G4: =F4+7 -> 46081 | I4: TOTAL
C5: TITHE | D5: ='SABBATH 1'!C160 -> 70623 | E5: ='SABBATH 2'!C157 -> 103901 | F5: ='SABBAATH 3'!C120 -> 56147 | G5: ='SABBATH 4'!C106 -> 172641 | I5: =SUM(D5:H5) -> 403312
C6: COMBINED OFFERING 50% | D6: ='SABBATH 1'!C161 -> 2834.5 | E6: ='SABBATH 2'!C158 -> 8829.5 | F6: ='SABBAATH 3'!C121 -> 3627.5 | G6: ='SABBATH 4'!C107 -> 3455 | I6: =SUM(D6:H6) -> 18746.5
C7: THANKS GIVING 50% | D7: ='SABBATH 1'!C163 -> 2925 | E7: ='SABBATH 2'!C160 -> 350 | F7: ='SABBAATH 3'!C123 -> 2700 | G7: ='SABBATH 4'!C109 -> 650 | I7: =SUM(D7:H7) -> 6625
C8: 13TH SABBATH OFFERING | D8: 0 | E8: 0 | F8: 0 | G8: 0 | I8: =SUM(D8:H8) -> 0
C9: CAMP OFFERING | D9: ='SABBATH 1'!C162 -> 385 | E9: ='SABBATH 2'!C159 -> 740 | F9: ='SABBAATH 3'!C122 -> 200 | G9: ='SABBATH 4'!C108 -> 760 | I9: =SUM(D9:H9) -> 2085
C10: STATION DEVELOPMENT | D10: ='SABBATH 1'!C165 -> 0 | E10: ='SABBATH 2'!C162 -> 0 | F10: ='SABBAATH 3'!C125 -> 0 | G10: ='SABBATH 4'!C111 -> 0 | I10: =SUM(D10:H10) -> 0
C11: FIELD EVANGELISM | D11: ='SABBATH 1'!C164 -> 0 | E11: ='SABBATH 2'!C161 -> 0 | F11: ='SABBAATH 3'!C124 -> 0 | G11: ='SABBATH 4'!C110 -> 0 | I11: =SUM(D11:H11) -> 0
C12: TOTAL TRUST FUNDS | D12: =SUM(D5:D11) -> 76767.5 | E12: =SUM(E5:E11) -> 113820.5 | F12: =SUM(F5:F11) -> 62674.5 | G12: =SUM(G5:G11) -> 177506 | I12: =SUM(I5:I11) -> 430768.5
C14: COMBINED OFFERING 50% | D14: ='SABBATH 1'!C169 -> 2834.5 | E14: =E6 -> 8829.5 | F14: ='SABBAATH 3'!C129 -> 3627.5 | G14: ='SABBATH 4'!C115 -> 3455 | I14: =SUM(D14:H14) -> 18746.5
C15: THANKS GIVING 50% | D15: ='SABBATH 1'!C170 -> 2925 | E15: ='SABBATH 2'!C167 -> 350 | F15: ='SABBAATH 3'!C130 -> 2700 | G15: ='SABBATH 4'!C116 -> 650 | I15: =SUM(D15:H15) -> 6625
C16: CHURCH BUDGET | D16: ='SABBATH 1'!C173 -> 4570 | E16: ='SABBATH 2'!C170 -> 6650 | F16: ='SABBAATH 3'!C134 -> 13870 | G16: ='SABBATH 4'!C119 -> 5800 | I16: =SUM(D16:H16) -> 30890
C17: EVANGELISM LOCAL | D17: ='SABBATH 1'!C171 -> 0 | E17: ='SABBATH 2'!C168 -> 0 | G17: ='SABBATH 4'!C117 -> 0 | I17: =SUM(D17:H17) -> 0
C18: DEVELOPMENT | D18: ='SABBATH 1'!C172 -> 23835 | E18: ='SABBATH 2'!C169 -> 3010 | F18: ='SABBAATH 3'!C132 -> 880 | G18: ='SABBATH 4'!C118 -> 20125 | I18: =SUM(D18:H18) -> 47850
C19: SABBATH SCHOOL | D19: 0 | E19: ='SABBATH 2'!C172 -> 160 | F19: ='SABBAATH 3'!C131 -> 30 | G19: ='SABBATH 4'!C120 -> 100 | I19: =SUM(D19:H19) -> 290
C20: PATHFINDER REG | D20: ='SABBATH 1'!C174 -> 200 | E20: ='SABBATH 2'!C173 -> 0 | I20: =SUM(D20:H20) -> 200
C21: MSAMARIA | D21: 0 | E21: ='SABBATH 2'!C174 -> 1550 | F21: ='SABBAATH 3'!C133 -> 0 | I21: =SUM(D21:H21) -> 1550
C22: TOTAL CHURCH FUNDS | D22: =SUM(D14:D21) -> 34364.5 | E22: =SUM(E14:E21) -> 20549.5 | F22: =SUM(F14:F21) -> 21107.5 | G22: =SUM(G14:G21) -> 30130 | H22: =SUM(H14:H21) -> 0 | I22: =SUM(I14:I21) -> 106151.5
C24: TOTAL COLLECTION | D24: =D22+D12 -> 111132 | E24: =E22+E12 -> 134370 | F24: =F22+F12 -> 83782 | G24: =G22+G12 -> 207636 | H24: =H22+H12 -> 0 | I24: =SUM(D24:H24) -> 536920
C28: TREASURER: | D28: EDWIN K. ORIOKI | E28: ELDER: | F28: CALVINCE OUMA | G28: PASTOR: | H28: MACJOE MASESI
C29: SIGNATURE: | E29: SIGNATURE: | G29: SIGNATURE:
C30: DATE: | E30: DATE: | G30: DATE:

Sheet 4TH MARCH 2023
C2: TREASURERS CASH STATEMENT, 4TH MARCH 2023
A3: Date | B3: Contributor Name | C3: Receipt Number | D3: Total Amount | E3: Tithe | F3: Combined Offerings | G3: Camp Meeting | H3: Church Building Fund | I3: Local Church Budget | J3: Thanks Giving | K3: Evangelism-Field | L3: Evangelism-local | M3: Chairs | N3: GYD | O3: Sabbath School | P3: Master Guide | Q3: Station Dev. Fund | R3: Adventist Possibility Ministry (APM)
A4: 44989 | B4: KAHAWA SUKARI SDA | C4: 506436 | D4: 8151 | I4: 8151
A5: 44989 | B5: ZIPPORAH MAIRURA | C5: 506437 | D5: 300 | R5: 300
A6: 44989 | B6: DAMARIS WAMBUI KAMAU | C6: 506438 | D6: 200 | F6: 200
A7: 44989 | B7: ABEDNEGO GWAYA | C7: 506439 | D7: 220000 | H7: 220000
A8: 44989 | B8: CECILIA ATUTI | C8: 506440 | D8: 1000 | I8: 1000
A9: 44989 | B9: DR.(MRS.) TERESA NYAMBEGERA | C9: 506441 | D9: 12000 | E9: 11000 | F9: 200 | I9: 800
A10: 44989 | B10: CHELSEY KIOKO | C10: 506442 | D10: 60 | E10: 50 | F10: 10
A11: 44989 | B11: DENISH OTIENO | C11: 506443 | D11: 200 | E11: 200
A12: 44989 | B12: JACINTA MARUTI | C12: 506444 | D12: 100 | E12: 50 | F12: 50
A13: 44989 | B13: JOSEPHINE MORANGA | C13: 506445 | D13: 200 | E13: 100 | H13: 100
A14: 44989 | B14: ZAINABU ISRAEL | C14: 506446 | D14: 700 | E14: 700
A15: 44989 | B15: FAITH KORIR | C15: 506447 | D15: 700 | E15: 700
A16: 44989 | B16: MARY MIRINGA | C16: 506448 | D16: 200 | I16: 200
A17: 44989 | B17: BRENDA JUMBE | C17: 506449 | D17: 200 | E17: 100 | I17: 100
A18: 44989 | B18: EMILY OYUGI | C18: 506450 | D18: 600 | F18: 300 | I18: 300
A19: 44989 | B19: ABEDNEGO GWAYA | C19: 506451 | D19: 1000 | F19: 1000
A20: 44989 | B20: NATHANIEL NYAGOL | C20: 506452 | D20: 300 | E20: 300
A21: 44989 | B21: BETTY MWANGI | C21: 506453 | D21: 6000 | E21: 5700 | F21: 300
A22: 44989 | B22: RAHAB NYAKUNDI | C22: 506454 | D22: 100 | F22: 100
A23: 44989 | B23: BENFILAS JUMA | C23: 506455 | D23: 200 | F23: 50 | H23: 150
A24: 44989 | B24: SILAS MBECHE | C24: 506456 | D24: 200 | E24: 100 | I24: 100
A25: 44989 | B25: JUSTUS OKENYE | C25: 506457 | D25: 200 | G25: 100 | I25: 100
A26: 44989 | B26: MARTHA MAKORI | C26: 506458 | D26: 100 | F26: 50 | K26: 50
A27: 44989 | B27: NGIGI KARANJA | C27: 506459 | D27: 200 | F27: 200
A28: 44989 | B28: DOMINIC GICHANA | C28: 506460 | D28: 240 | E28: 240
A29: 44989 | B29: FRIDAH NKUNDA | C29: 506461 | D29: 50 | F29: 50
A30: 44989 | B30: ANNAH OSEBE | C30: 506462 | D30: 100 | K30: 100
A31: 44989 | B31: LILIAN OMBAYE | C31: 506463 | D31: 500 | F31: 500
A32: 44989 | B32: TITUS NDIWA’S FAMILY | C32: 506464 | D32: 1000 | F32: 500 | I32: 500
A33: 44989 | B33: ADRIELLE CORRIDLO | C33: 506465 | D33: 100 | E33: 100
A34: 44989 | B34: LUCY OMWENO | C34: 506466 | D34: 2000 | I34: 2000
A35: 44989 | B35: LYDIA MORAA | C35: 506467 | D35: 2200 | F35: 2200
A36: 44989 | B36: MARTINAH NYAKUNDI | C36: 506468 | D36: 5000 | E36: 4689 | I36: 311
A37: 44989 | B37: NIRAH | C37: 506469 | D37: 500 | E37: 500
A38: 44989 | B38: SARAH OTHOO | C38: 506470 | D38: 300 | E38: 250 | F38: 50
A39: 44989 | B39: RAQUEL MODI | C39: 506471 | D39: 3500 | E39: 3500
A40: 44989 | B40: NO NAME | C40: 506472 | D40: 1000 | I40: 1000
A41: 44989 | B41: OMBATI WILSON | C41: 506473 | D41: 29000 | E41: 20800 | H41: 5200 | M41: 2000 | N41: 1000
...

Sheet 4TH-EXPENSES
C2: LOCAL CHURCH -EXPENSES
C3: DESCRIPTION | D3: DATE | E3: AMOUNT
C4: Deaconary Funds for March 2023 | D4: 44989 | E4: 28820
C5: Pr. Facilitation within the week | D5: 44989 | E5: 4000
C6: Speaker facilitation-Stewarship week of prayer | D6: 44989 | E6: 10000
C7: Additional Lunch for the Funds Drive-Visitors | D7: 44989 | E7: 4000
C8: Bulletin Printing (2 sabbaths) | D8: 44989 | E8: 1200
C21: TOTALS | E21: =SUM(E4:E20) -> 48020

Sheet 11TH MARCH 2023
C2: TREASURERS CASH STATEMENT, 11TH MARCH 2023
A3: Date | B3: Contributor Name | C3: Receipt Number | D3: Total Amount | E3: Tithe | F3: Combined Offerings | G3: Camp Meeting | H3: Church Building Fund | I3: Local Church Budget | J3: Thanks Giving | K3: Evangelism-Field | L3: Evangelism-local | M3: Chairs | N3: GYD | O3: Sabbath School | P3: Master Guide | Q3: Station Dev. Fund | R3: Adventist Possibility Ministry (APM)
A4: 44996 | B4: CHARLES GICHUKI | C4: 506522 | D4: 100 | H4: 100
A5: 44996 | B5: MARTHA BOCHERE | C5: 506523 | D5: 100 | E5: 50 | F5: 50
A6: 44996 | B6: LUCAS N. NYAMBEGERA | C6: 506524 | D6: 10000 | E6: 8000 | I6: 2000
A7: 44996 | B7: JOSPHAT MAIKARA | C7: 506525 | D7: 1000 | F7: 1000
A8: 44996 | B8: DAMARIS WWMBUI KAMAU | C8: 506526 | D8: 100 | F8: 100
A9: 44996 | B9: NGIGI KARANJA | C9: 506527 | D9: 200 | F9: 200
A10: 44996 | B10: LINET KEMUNTO | C10: 506528 | D10: 1000 | E10: 1000
A11: 44996 | B11: ACHIENG LENCER | C11: 506529 | D11: 20 | E11: 20
A12: 44996 | B12: ELIZABETH N. KIMONGE | C12: 506530 | D12: 500 | F12: 300 | I12: 200
A13: 44996 | B13: SPINGS OGUGU | C13: 506531 | D13: 500 | H13: 500
A14: 44996 | B14: ROSE NYAMAO MAGOMA | C14: 506532 | D14: 3000 | F14: 1000 | H14: 2000
A15: 44996 | B15: JUSTUS OKENYE | C15: 506533 | D15: 200 | G15: 100 | I15: 50 | K15: 50
A16: 44996 | B16: SHELINE OYOO | C16: 506534 | D16: 4000 | E16: 3900 | F16: 100
A17: 44996 | B17: JOSEPHINE MORANGA | C17: 506535 | D17: 100 | E17: 100
A18: 44996 | B18: TAMARA ADHIAMBO | C18: 506536 | D18: 20 | E18: 20
A19: 44996 | B19: MERCYLINE NYANKIRA | C19: 506537 | D19: 200 | E19: 200
A20: 44996 | B20: EMILY OYUGI | C20: 506538 | D20: 500 | F20: 200 | I20: 300
A21: 44996 | B21: ANNAH OSEBE | C21: 506539 | D21: 500 | I21: 100 | J21: 400
A22: 44996 | B22: NO NAME | C22: 506540 | D22: 20 | H22: 20
A23: 44996 | B23: RAHAB NYAKUNDI | C23: 506541 | D23: 750 | E23: 750
A24: 44996 | B24: JEMMY JAMES | C24: 506542 | D24: 100 | E24: 100
A25: 44996 | B25: EVANS TSOMBE | C25: 506543 | D25: 200 | E25: 200
A26: 44996 | B26: IBRAHIM NYABUTI | C26: 506544 | D26: 500 | E26: 500
A27: 44996 | B27: DORIS NYAMARI | C27: 506545 | D27: 100 | P27: 100
A28: 44996 | B28: DR.(MRS.) TERESA NYAMBEGERA | C28: 506546 | D28: 1000 | F28: 200 | I28: 800
A29: 44996 | B29: JACINTA KIPROP | C29: 506547 | D29: 100 | H29: 100
A30: 44996 | B30: MONYENYE OMBATI | C30: 506548 | D30: 500 | H30: 500
A31: 44996 | B31: LILIAN OMBAYE | C31: 506549 | D31: 500 | H31: 500
A32: 44996 | B32: EDNAH OBAIGWA | C32: 506550 | D32: 100 | H32: 100
A33: 44996 | B33: DRUSILLA MAKWORO | C33: 506551 | D33: 5000 | H33: 5000
A34: 44996 | B34: EMILY OYUGI | C34: 506552 | D34: 2000 | H34: 2000
A35: 44996 | B35: STELLAH MASESE | C35: 506553 | D35: 1000 | H35: 1000
A36: 44996 | B36: LINET KEMUNTO | C36: 506554 | D36: 1000 | H36: 1000
A37: 44996 | B37: DAMARIS WWMBUI KAMAU | C37: 506555 | D37: 500 | H37: 500
A38: 44996 | B38: KEFA GEKONDE | C38: 506556 | D38: 1000 | H38: 1000
A39: 44996 | B39: YABESH KIBAI | C39: 506557 | D39: 3000 | H39: 3000
A40: 44996 | B40: BENFILAS JUMA | C40: 506558 | D40: 1150 | F40: 50 | H40: 1100
A41: 44996 | B41: MICAH MAKWORO | C41: 506559 | D41: 35000 | H41: 35000
...

Sheet 11TH-EXPENSES
C2: LOCAL CHURCH -EXPENSES
C3: DESCRIPTION | D3: DATE | E3: AMOUNT
C4: Internet Payment | D4: 44996 | E4: 5800
C5: Garbage collection fee (Nov 2022 to Feb 2023) | D5: 44996 | E5: 1200
C6: GYD collection Payout | D6: 44996 | E6: 13300
C7: GYD Youth Lunch | D7: 44996 | E7: 3000
C8: GYD Adventurers Lunch | D8: 44996 | E8: 3000
C9: GYD Ambasdors Lunch | D9: 44996 | E9: 900
C21: TOTALS | E21: =SUM(E4:E20) -> 27200

Sheet 18TH MARCH 2023
C2: TREASURERS CASH STATEMENT, 18TH MARCH 2023
A3: Date | B3: Contributor Name | C3: Receipt Number | D3: Total Amount | E3: Tithe | F3: Combined Offerings | G3: Camp Meeting | H3: Church Building Fund | I3: Local Church Budget | J3: Thanks Giving | K3: Evangelism-Field | L3: Evangelism-local | M3: Chairs | N3: GYD | O3: Sabbath School | P3: Master Guide | Q3: Station Dev. Fund | R3: Adventist Possibility Ministry (APM)
A4: 45003 | B4: NATHANIEL NYAGOL | C4: 528521 | D4: 1000 | E4: 1000
A5: 45003 | B5: OBUYA'S FAMILY | C5: =C4+1 -> 528522 | D5: 6000 | E5: 2000 | F5: 2000 | H5: 2000
A6: 45003 | B6: HELLEN OGENCHE | C6: =C5+1 -> 528523 | D6: 200 | E6: 200
A7: 45003 | B7: DOROTHY NGALA | C7: =C6+1 -> 528524 | D7: 1000 | F7: 1000
A8: 45003 | B8: KEFA GEKONDE | C8: =C7+1 -> 528525 | D8: 1000 | E8: 1000
A9: 45003 | B9: MR. & MRS. ERICK GWARO | C9: =C8+1 -> 528526 | D9: 6000 | E9: 5500 | F9: 500
A10: 45003 | B10: NYAMARI GEKONDE | C10: =C9+1 -> 528527 | D10: 107000 | E10: 106000 | I10: 1000
A11: 45003 | B11: YABESH KIBAI | C11: =C10+1 -> 528528 | D11: 100 | I11: 100
A12: 45003 | B12: ANNAH OSEBE | C12: =C11+1 -> 528529 | D12: 300 | J12: 200 | K12: 100
A13: 45003 | B13: OMBATI WILSON | C13: =C12+1 -> 528530 | D13: 3000 | H13: 3000
A14: 45003 | B14: NGIGI KARANJA | C14: =C13+1 -> 528531 | D14: 200 | F14: 200
A15: 45003 | B15: EMILY OYUGI | C15: =C14+1 -> 528532 | D15: 500 | F15: 200 | I15: 300
A16: 45003 | B16: LINET KEMUNTO | C16: =C15+1 -> 528533 | D16: 200 | I16: 200
A17: 45003 | B17: CORNELIUS KIPTOO | C17: =C16+1 -> 528534 | D17: 1000 | E17: 1000
A18: 45003 | B18: NDIWA'S FAMILY | C18: =C17+1 -> 528535 | D18: 1000 | E18: 1000
A19: 45003 | B19: MIRRIAM WEISIKO | C19: =C18+1 -> 528536 | D19: 200 | I19: 200
A20: 45003 | B20: RHODA NYANDUKO | C20: =C19+1 -> 528537 | D20: 100 | F20: 100
A21: 45003 | B21: JUSTUS OKENYE | C21: =C20+1 -> 528538 | D21: 200 | F21: 100 | I21: 50 | K21: 50
A22: 45003 | B22: ZADIAN ANGWENYI | C22: =C21+1 -> 528539 | D22: 500 | J22: 500
A23: 45003 | B23: JOSEPH MORANGÁ | C23: =C22+1 -> 528540 | D23: 100 | E23: 100
A24: 45003 | B24: JOSEPHAT NYAGERO | C24: =C23+1 -> 528541 | D24: 200 | F24: 200
A25: 45003 | B25: BENFILAS JUMA | C25: =C24+1 -> 528542 | D25: 200 | F25: 50 | H25: 150
A26: 45003 | B26: LUCY OMWENO | C26: =C25+1 -> 528543 | D26: 2000 | I26: 2000
A27: 45003 | B27: ESTHER KWAMBOKA | C27: =C26+1 -> 528544 | D27: 200 | E27: 200
A28: 45003 | B28: DAMARIS WAMBUI | C28: =C27+1 -> 528545 | D28: 100 | F28: 100
A29: 45003 | B29: PRINCESS ERICK LUCAS | C29: =C28+1 -> 528546 | D29: 200 | E29: 200
A30: 45003 | B30: ELIZABETH KIMONGE | C30: =C29+1 -> 528547 | D30: 500 | F30: 300 | I30: 200
A31: 45003 | B31: KAHAWA SUKARI | C31: =C30+1 -> 528548 | D31: 5124 | I31: 5124
A32: 45003 | B32: ESTHER MOMANYI | C32: =C31+1 -> 528549 | D32: 1000 | N32: 1000
A33: 45003 | B33: CELESTINE NYANCHAMA | C33: =C32+1 -> 528550 | D33: 100 | N33: 100
A34: 45003 | B34: SILAS MBECHE | C34: =C33+1 -> 528551 | D34: 500 | N34: 500
A35: 45003 | B35: DOMINIC GICHANA | C35: =C34+1 -> 528552 | D35: 120 | E35: 120
A36: 45003 | B36: BONFACE OSINDI | C36: =C35+1 -> 528553 | D36: 150 | E36: 150
A37: 45003 | B37: JILLANI YAWA | C37: =C36+1 -> 528554 | D37: 40000 | H37: 40000
A38: 45003 | B38: MARY GEKONDE | C38: =C37+1 -> 528555 | D38: 60 | E38: 60
A39: 45003 | B39: STANLEY MACHARIA | C39: =C38+1 -> 528556 | D39: 50 | E39: 50
A40: 45003 | B40: VINCENT NGÉNO | C40: =C39+1 -> 528557 | D40: 30000 | H40: 30000
A41: 45003 | B41: ERICK GWARO | C41: =C40+1 -> 528558 | D41: 900 | E41: 900
...

Sheet 18TH-EXPENSES
C2: LOCAL CHURCH -EXPENSES
C3: DESCRIPTION | D3: DATE | E3: AMOUNT
C4: Fuel and transport | D4: 45003 | E4: 2000
C5: Water Tank Refill (5000L) | D5: 45003 | E5: 2500
C6: KPLC Power bill | D6: 45003 | E6: 19500
C7: Internet payment | D7: 45003 | E7: 800
C21: TOTALS | E21: =SUM(E4:E20) -> 24800

Sheet 25TH MARCH 2023
C2: TREASURERS CASH STATEMENT, 25TH MARCH 2023
A3: Date | B3: Contributor Name | C3: Receipt Number | D3: Total Amount | E3: Tithe | F3: Combined Offerings | G3: Camp Meeting | H3: Church Building Fund | I3: Local Church Budget | J3: Thanks Giving | K3: Evangelism-Field | L3: Evangelism-local | M3: Chairs | N3: GYD | O3: Sabbath School | P3: Master Guide | Q3: Station Dev. Fund | R3: Lunch
A4: 45010 | B4: Kahawa Sukari | C4: 528588 | D4: 6282 | I4: 6282
A5: 45010 | B5: Wilson Ombati | C5: 528589 | D5: 13000 | E5: 12000 | M5: 1000
A6: 45010 | B6: Jacinta Maruti | C6: 528590 | D6: 50 | F6: 50
A7: 45010 | B7: Mary Gekonde | C7: 528591 | D7: 2500 | E7: 2500
A8: 45010 | B8: Monyenye Ombati | C8: 528592 | D8: 16000 | E8: 15720 | G8: 280
A9: 45010 | B9: Eucabeth Mosero | C9: 528593 | D9: 200 | E9: 200
A10: 45010 | B10: Bernad Ondara | C10: 528594 | D10: 1000 | I10: 500 | K10: 500
A11: 45010 | B11: Josphat Maikara | C11: 528595 | D11: 1000 | F11: 1000
A12: 45010 | B12: Rahab Nyakundi | C12: 528596 | D12: 220 | E12: 120 | F12: 100
A13: 45010 | B13: Yabesh Kibai | C13: 528597 | D13: 100 | I13: 100
A14: 45010 | B14: Denish Otieno | C14: 528598 | D14: 100 | E14: 100
A15: 45010 | B15: Mr & Mrs Eric Gwaro | C15: 528599 | D15: 100 | I15: 100
A16: 45010 | B16: Gakubu Ruth | C16: 528600 | D16: 90 | E16: 90
A17: 45010 | B17: Mr & Mrs Vincent Onchweri | C17: 499801 | D17: 1000 | E17: 500 | F17: 500
A18: 45010 | B18: Eng Okoth | C18: 499802 | D18: 4000 | I18: 3500 | R18: 500
A19: 45010 | B19: Karen Kaunda | C19: 499803 | D19: 2000 | E19: 2000
A20: 45010 | B20: No Name | C20: 499804 | D20: 200 | E20: 200
A21: 45010 | B21: Ruth Mining | C21: 499805 | D21: 1700 | E21: 1700
A22: 45010 | B22: Alphonce Manyoni | C22: 499806 | D22: 200 | F22: 100 | J22: 100
A23: 45010 | B23: No Name | C23: 499807 | D23: 200 | I23: 200
A24: 45010 | B24: Mary Miringa | C24: 499808 | D24: 200 | I24: 200
A25: 45010 | B25: Ndiwas | C25: 499809 | D25: 200 | E25: 200
A26: 45010 | B26: Rosemary Manywanda | C26: 499810 | D26: 6000 | E26: 5800 | R26: 200
A27: 45010 | B27: Benfilas Juma | C27: 499811 | D27: 200 | F27: 50 | H27: 150
A28: 45010 | B28: Tabitha Akinyi | C28: 499812 | D28: 200 | E28: 150 | I28: 50
A29: 45010 | B29: Emelda Vai | C29: 499813 | D29: 1600 | E29: 1500 | F29: 100
A30: 45010 | B30: Lucas Nyangweso | C30: 499814 | D30: 200 | I30: 200
A31: 45010 | B31: Emily Oyugi | C31: 499815 | D31: 500 | F31: 200 | I31: 300
A32: 45010 | B32: Evans Ogato | C32: 499816 | D32: 430 | E32: 430
A33: 45010 | B33: Mrs Roggers Abongo | C33: 499817 | D33: 500 | E33: 500
A34: 45010 | B34: Tabitha Onserio | C34: 499818 | D34: 200 | I34: 200
A35: 45010 | B35: Cornelius Kiptoo | C35: 499819 | D35: 1000 | E35: 800 | H35: 200
A36: 45010 | B36: Elizabeth Kimonge | C36: 499820 | D36: 1150 | G36: 1000 | I36: 150
A37: 45010 | B37: Brenda Jumbe | C37: 499821 | D37: 400 | E37: 300 | I37: 50 | K37: 50
A38: 45010 | B38: Annah Osebe | C38: 499822 | D38: 10300 | H38: 10000 | I38: 100 | J38: 200
A39: 45010 | B39: Ruth Moindi | C39: 499823 | D39: 800 | H39: 800
A40: 45010 | B40: Winnie Akinyi | C40: 499824 | D40: 200 | E40: 200
A41: 45010 | B41: Zadrian Makori | C41: 499825 | D41: 1000 | H41: 1000
...

Sheet SABBATH 1
A2: No | B2: CONTRIBUTOR NAME | C2: RECEIPT NUMBER | D2: TOTAL | E2: TITHE | F2: COMBINED OFFERINGS | G2: CAMP MEETING OFFERINGS | H2: CHURCH BUILDING FUND | I2: LOCAL CHURCH BUDGET (LCB) | J2: THANKS GIVING | K2: PATHFINDER REG
A3: 1 | B3: WESLEY MATOKE | C3: 84169 | D3: 200 | H3: 200 | L3: =SUM(E3:K3)-D3 -> 0
A4: 2 | B4: SAMUEL KERAUNI | C4: 84170 | D4: 500 | H4: 500 | L4: =SUM(E4:K4)-D4 -> 0
A5: 3 | B5: ELVINA BOSIBORI | C5: 84171 | D5: 100 | E5: 100 | L5: =SUM(E5:K5)-D5 -> 0
A6: 4 | B6: WYCLIFF ONSANGO | C6: 84172 | D6: 100 | E6: 100 | L6: =SUM(E6:K6)-D6 -> 0
A7: 5 | B7: EMILY MOGAKA | C7: 84173 | D7: 100 | H7: 100 | L7: =SUM(E7:K7)-D7 -> 0
A8: 6 | B8: MARY KEMUNTO | C8: 84174 | D8: 50 | F8: 25 | G8: 25 | L8: =SUM(E8:K8)-D8 -> 0
A9: 7 | B9: ELIAZAR ONGARA | C9: 84175 | D9: 500 | E9: 500 | L9: =SUM(E9:K9)-D9 -> 0
A10: 8 | B10: ESTHER MBONE | C10: 84176 | D10: 200 | H10: 200 | L10: =SUM(E10:K10)-D10 -> 0
A11: 9 | B11: VERONICAH KIMANI | C11: 84177 | D11: 200 | E11: 200 | L11: =SUM(E11:K11)-D11 -> 0
A12: 10 | B12: FAITH KERUBO | C12: 84178 | D12: 200 | H12: 200 | L12: =SUM(E12:K12)-D12 -> 0
A13: 11 | B13: JULIET ORURU | C13: 84179 | D13: 200 | F13: 200 | L13: =SUM(E13:K13)-D13 -> 0
A14: 12 | B14: LAVINA ALELA | C14: 84180 | D14: 200 | E14: 100 | F14: 50 | G14: 50 | L14: =SUM(E14:K14)-D14 -> 0
A15: 13 | B15: MARTHA BITENGO | C15: 84181 | D15: 50 | E15: 50 | L15: =SUM(E15:K15)-D15 -> 0
A16: 14 | B16: ELSA BISIERI OUKO | C16: 84182 | D16: 50 | F16: 50 | L16: =SUM(E16:K16)-D16 -> 0
A17: 15 | B17: REBECCA OGUTU | C17: 84183 | D17: 50 | I17: 50 | L17: =SUM(E17:K17)-D17 -> 0
A18: 16 | B18: ALBERT MAINA | C18: 84184 | D18: 4000 | E18: 4000 | L18: =SUM(E18:K18)-D18 -> 0
A19: 17 | B19: MANYALA JOHN | C19: 84185 | D19: 300 | E19: 100 | H19: 200 | L19: =SUM(E19:K19)-D19 -> 0
A20: 18 | B20: MILKA NYANJAMA | C20: 84186 | D20: 100 | E20: 100 | L20: =SUM(E20:K20)-D20 -> 0
A21: 19 | B21: VALLENCY JUSTICE | C21: 84187 | D21: 100 | E21: 50 | H21: 50 | L21: =SUM(E21:K21)-D21 -> 0
A22: 20 | B22: TIMOTHY OMARE | C22: 84188 | D22: 200 | F22: 100 | I22: 100 | L22: =SUM(E22:K22)-D22 -> 0
A23: 21 | B23: JOHNES JUMA | C23: 84189 | D23: 100 | F23: 100 | L23: =SUM(E23:K23)-D23 -> 0
A24: 22 | B24: JOSEPHINE NYAKOE | C24: 84190 | D24: 1000 | H24: 1000 | L24: =SUM(E24:K24)-D24 -> 0
A25: 23 | B25: DANIEL NJOROGE | C25: 84191 | D25: 50 | H25: 50 | L25: =SUM(E25:K25)-D25 -> 0
A26: 24 | B26: ELIJAH PAPAI | C26: 84192 | D26: 500 | H26: 500 | L26: =SUM(E26:K26)-D26 -> 0
A27: 25 | B27: MAXWEL ODHIAMBO | C27: 84193 | D27: 1000 | H27: 1000 | L27: =SUM(E27:K27)-D27 -> 0
A28: 26 | B28: WILFRED NYAOSI | C28: 84194 | D28: 150 | E28: 150 | L28: =SUM(E28:K28)-D28 -> 0
A29: 27 | B29: BRIAN OMENYI | C29: 84195 | D29: 500 | I29: 500 | L29: =SUM(E29:K29)-D29 -> 0
A30: 28 | B30: ERICK OMOSA | C30: 84196 | D30: 1000 | F30: 1000 | L30: =SUM(E30:K30)-D30 -> 0
A31: 29 | B31: JOHN MOMANYI | C31: 84197 | D31: 2000 | H31: 2000 | L31: =SUM(E31:K31)-D31 -> 0
A32: 30 | B32: ELDER OUMA'S FAMILY | C32: 84198 | D32: 400 | G32: 200 | I32: 200 | L32: =SUM(E32:K32)-D32 -> 0
A33: 31 | B33: OTISO MOSES | C33: 84199 | D33: 50 | E33: 15 | F33: 15 | G33: 10 | H33: 10 | L33: =SUM(E33:K33)-D33 -> 0
A34: 32 | B34: NANCY OBARE | C34: 84200 | D34: 7026 | E34: 7026 | L34: =SUM(E34:K34)-D34 -> 0
A35: 33 | B35: ELEN KIMANI | C35: 262201 | D35: 2265 | E35: 2265 | L35: =SUM(E35:K35)-D35 -> 0
A36: 34 | B36: JESSA ADHIAMBO | C36: 262202 | D36: 100 | E36: 100 | L36: =SUM(E36:K36)-D36 -> 0
A37: 35 | B37: SAMUEL OGEMBO | C37: 262203 | D37: 100 | I37: 100 | L37: =SUM(E37:K37)-D37 -> 0
A38: 36 | B38: CLIFFORD SIOCHA | C38: 262204 | D38: 1000 | I38: 1000 | L38: =SUM(E38:K38)-D38 -> 0
A39: 37 | B39: FELIX MUSIU | C39: 262205 | D39: 100 | I39: 100 | L39: =SUM(E39:K39)-D39 -> 0
A40: 38 | B40: CHERYL ORIOKI | C40: 262206 | D40: 5000 | E40: 5000 | L40: =SUM(E40:K40)-D40 -> 0
A41: 39 | B41: BENEDICT ODHIAMBO | C41: 262207 | D41: 500 | E41: 500 | L41: =SUM(E41:K41)-D41 -> 0
...

Sheet SABBATH 2
A1: TREASURERS CASH STATEMENT 14 FEB 2026
A2: No | B2: CONTRIBUTOR NAME | C2: RECEIPT NUMBER | D2: TOTAL AMOUNT | E2: TITHE | F2: COMBINED OFFERINGS | G2: CAMP MEETING OFFERINGS | H2: CHURCH BUILDING FUND | I2: LOCAL CHURCH BUDGET (LCB) | J2: THANKS GIVING | K2: SABBATH SCHOOL | L2: EVANGELISM LOCAL
A3: 1 | B3: DAMARIS | C3: 262249 | D3: 100 | F3: 100
A4: 2 | B4: EMMACULATE OCHIENG | C4: 262250 | D4: 100 | E4: 30 | F4: 30 | H4: 40
A5: 3 | B5: EVERLYNE ARIKA | C5: 262251 | D5: 100 | E5: 50 | I5: 50
A6: 4 | B6: WINNNIE REBECCA | C6: 262252 | D6: 200 | E6: 100 | F6: 50 | G6: 50
A7: 5 | B7: ROGERS MACHOKA | C7: 262253 | D7: 1000 | E7: 500 | F7: 500
A8: 6 | B8: ETHAN AND ADRIEL | C8: 262254 | D8: 100 | F8: 100
A9: 7 | B9: GRACE OGOLA | C9: 262255 | D9: 300 | F9: 100 | I9: 200
A10: 8 | B10: SHERYL M | C10: 262256 | D10: 100 | F10: 100
A11: 9 | B11: SHANTELLE MUMBO | C11: 262257 | D11: 100 | F11: 100
A12: 10 | B12: LENCER OKWAH | C12: 262258 | D12: 200 | I12: 200
A13: 11 | B13: ROSELYNE AOKO | C13: 262259 | D13: 50 | F13: 50
A14: 12 | B14: JANICE CHAYA | C14: 262260 | D14: 50 | E14: 20 | F14: 20 | G14: 10
A15: 13 | B15: KENNEDY AKECH | C15: 262261 | D15: 100 | E15: 100
A16: 14 | B16: WANJARA LYDIA | C16: 262262 | D16: 100 | E16: 100
A17: 15 | B17: BEAUTTAH NYAUMA | C17: 262263 | D17: 200 | I17: 200
A18: 16 | B18: MILKA NYANJAMA | C18: 262264 | D18: 50 | E18: 50
A19: 17 | B19: ADHER BITUTU | C19: 262265 | D19: 200 | F19: 100 | G19: 50 | I19: 50
A20: 18 | B20: LAVINA ALELA | C20: 262266 | D20: 150 | E20: 100 | G20: 30 | H20: 20
A21: 19 | B21: ELD. JAMES MIRERI | C21: 262267 | D21: 500 | E21: 100 | F21: 100 | G21: 100 | H21: 200
A22: 20 | B22: NANCY OSORO | C22: 262268 | D22: 200 | E22: 200
A23: 21 | B23: NYABUTO OONGE | C23: 262269 | D23: 1300 | G23: 300 | I23: 1000
A24: 22 | B24: BRIAN OMENYI | C24: 262270 | D24: 38500 | E24: 38500
A25: 23 | B25: JUDITH ODOYO | C25: 262271 | D25: 400 | E25: 300 | H25: 100
A26: 24 | B26: CHERYL ORIOKI | C26: 262272 | D26: 200 | I26: 200
A27: 25 | B27: JEMIMAH NYOLOO | C27: 262273 | D27: 100 | H27: 100
A28: 26 | B28: SAMSON NYARERU | C28: 262274 | D28: 100 | F28: 50 | G28: 50
A29: 27 | B29: JOHN MOMANYI | C29: 262275 | D29: 1000 | H29: 1000
A30: 28 | B30: ERICK OMOSA | C30: 262276 | D30: 1000 | F30: 1000
A31: 29 | B31: JANE NYAMONGO | C31: 262277 | D31: 300 | I31: 300
A32: 30 | B32: GLADYS MOGOI | C32: 262278 | D32: 100 | E32: 100
A33: 31 | B33: NAOMI KWAMBOKA | C33: 262279 | D33: 500 | E33: 500
A34: 32 | B34: LINET MAGETO | C34: 262280 | D34: 1000 | E34: 700 | I34: 300
A35: 33 | B35: LAVINAH WYCLIFFE | C35: 262281 | D35: 200 | E35: 200
A36: 34 | B36: COLLINS MBOYA | C36: 262282 | D36: 50 | E36: 50
A37: 35 | B37: LIAM OROTO | C37: 262283 | D37: 100 | E37: 100
A38: 36 | B38: LEOMA LIVA | C38: 262284 | D38: 50 | I38: 50
A39: 37 | B39: KERINA OKUMU | C39: 262285 | D39: 100 | F39: 100
A40: 38 | B40: MILCAH MOKAMBA | C40: 262286 | D40: 30 | K40: 30
...

Sheet SABBAATH 3
A1: TREASURERS CASH STATEMENT, 21 FEB 2026
B2: CONTRIBUTOR NAME | C2: RECEIPT NUMBER | D2: TOTAL AMOUNT | E2: TITHE | F2: COMBINED OFFERINGS | G2: CAMP MEETING OFFERINGS | H2: CHURCH BUILDING FUND | I2: LOCAL CHURCH BUDGET (LCB) | J2: THANKS | K2: SABBATH SCHOOL
A3: 1 | B3: BILL OROTO | C3: 262320 | D3: 500 | I3: 500
A4: 2 | B4: LYDIAH MOTARI | C4: 262321 | D4: 100 | E4: 100
A5: 3 | B5: CHRSTINE KAWIRA | C5: 262322 | D5: 100 | F5: 100
A6: 4 | B6: HELLEN ABUGA | C6: 262323 | D6: 100 | I6: 100
A7: 5 | B7: JOHNES JUMA | C7: 262324 | D7: 50 | F7: 50
A8: 6 | B8: LAVINA ALELA | C8: 262325 | D8: 100 | E8: 50 | F8: 10 | G8: 20 | H8: 20
A9: 7 | B9: LIAM OROTO | C9: 262326 | D9: 100 | F9: 100
A10: 8 | B10: NAOMI KWAMBOKA | C10: 262327 | D10: 200 | E10: 200
A11: 9 | B11: DAMARIS OMBATI | C11: 262328 | D11: 100 | F11: 50 | I11: 50
A12: 10 | B12: NZIOKA SAMUEL | C12: 262329 | D12: 1000 | E12: 500 | F12: 500
A13: 11 | B13: VIOLET JUMA | C13: 262330 | D13: 8750 | E13: 8750
A14: 12 | B14: MARTHA BITENGO | C14: 262331 | D14: 100 | F14: 80 | I14: 20
A15: 13 | B15: EMMACULATE OCHIENG | C15: 262332 | D15: 50 | E15: 30 | G15: 20
A16: 14 | B16: CHRISTINE MOMANYI | C16: 262333 | D16: 50 | F16: 50
A17: 15 | B17: JOYCE MONGINA | C17: 262334 | D17: 100 | E17: 100
A18: 16 | B18: FLORENCE BOCHABERI | C18: 262335 | D18: 1000 | E18: 1000
A19: 17 | B19: BEAVON OSUMO | C19: 262336 | D19: 100 | E19: 100
A20: 18 | B20: BRIAN OSORO | C20: 262337 | D20: 200 | J20: 200
A21: 19 | B21: DAVIES JAMES | C21: 262338 | D21: 100 | E21: 100
A22: 20 | B22: BEAVON RORI | C22: 262339 | D22: 100 | E22: 100
A23: 21 | B23: CHARLES NDUNGU | C23: 262340 | D23: 85 | E23: 85
A24: 22 | B24: EDWIN EKIRAPA | C24: 262341 | D24: 200 | I24: 200
A25: 23 | B25: EVERLYNE OKEYO | C25: 262342 | D25: 50 | E25: 50
A26: 24 | B26: DIVINAH NYAKEYO | C26: 262343 | D26: 80 | E26: 80
A27: 25 | B27: ELIZAR ATULA | C27: 262344 | D27: 50 | E27: 50
A28: 26 | B28: FUN MISIANI | C28: 262345 | D28: 100 | E28: 100
A29: 27 | B29: HELLEN NAIMADU | C29: 262346 | D29: 5000 | J29: 5000
A30: 28 | B30: FREDRICK NYATEMU | C30: 262347 | D30: 100 | E30: 100
A31: 29 | B31: HILDER OUDU | C31: 262348 | D31: 200 | E31: 200
A32: 30 | B32: LEVINE OTIENO | C32: 262349 | D32: 50 | E32: 50
A33: 31 | B33: FIDEL OLUOCH | C33: 262350 | D33: 20 | E33: 20
A34: 32 | B34: JANET KARITHI | C34: 262351 | D34: 50 | E34: 50
A35: 33 | B35: GOULDAH MBYUTA | C35: 262352 | D35: 2500 | E35: 2300 | J35: 200
A36: 34 | B36: ELEN KIMANI | C36: 262353 | D36: 440 | E36: 440
A37: 35 | B37: CAROLINE K | C37: 262354 | D37: 20 | E37: 20
A38: 36 | B38: EVANS NYAKWARA | C38: 262355 | D38: 100 | I38: 100
A39: 37 | B39: DAVIS MIRONGA | C39: 262356 | D39: 1562 | E39: 1562
A40: 38 | B40: BRENDA AUMA | C40: 262357 | D40: 200 | F40: 200
...

Sheet SABBATH 4
A1: TREASURERS CASH STATEMENT, 28 FEB 2026
B2: CONTRIBUTOR NAME | C2: RECEIPT NUMBER | D2: TOTAL AMOUNT | E2: TITHE | F2: COMBINED OFFERINGS | G2: CAMP MEETING OFFERINGS | H2: CHURCH BUILDING FUND | I2: LOCAL CHURCH BUDGET (LCB) | J2: THANKS GIVING | K2: SABBATH SCHOOL
A3: 1 | B3: Dorice Chebet | C3: 262369 | D3: 100 | H3: 100 | L3: =SUM(E3:K3)-D3 -> 0
A4: 2 | B4: Gift Macvanne Momanyi | C4: 262370 | D4: 200 | F4: 200 | L4: =SUM(E4:K4)-D4 -> 0
A5: 3 | B5: Judith Odoyo | C5: 262371 | D5: 200 | E5: 200 | L5: =SUM(E5:K5)-D5 -> 0
A6: 4 | B6: Samwel Abaya | C6: 262372 | D6: 200 | F6: 100 | I6: 100 | L6: =SUM(E6:K6)-D6 -> 0
A7: 5 | B7: Brenda Awino | C7: 262373 | D7: 50 | E7: 50 | L7: =SUM(E7:K7)-D7 -> 0
A8: 6 | B8: Martha Bitengo | C8: 262374 | D8: 50 | F8: 50 | L8: =SUM(E8:K8)-D8 -> 0
A9: 7 | B9: Christine Kawira | C9: 262375 | D9: 100 | F9: 100 | L9: =SUM(E9:K9)-D9 -> 0
A10: 8 | B10: Daniel Njoroge | C10: 262376 | D10: 200 | E10: 200 | L10: =SUM(E10:K10)-D10 -> 0
A11: 9 | B11: Bill Oroto | C11: 262377 | D11: 500 | F11: 500 | L11: =SUM(E11:K11)-D11 -> 0
A12: 10 | B12: Sarah Abaya | C12: 262378 | D12: 10100 | E12: 10000 | I12: 100 | L12: =SUM(E12:K12)-D12 -> 0
A13: 11 | B13: Joy Mellen Faith | C13: 262379 | D13: 50 | F13: 50 | L13: =SUM(E13:K13)-D13 -> 0
A14: 12 | B14: Millicent Atieno | C14: 262380 | D14: 400 | F14: 200 | I14: 200 | L14: =SUM(E14:K14)-D14 -> 0
A15: 13 | B15: SYLIVIA ALWANGA | C15: 262381 | D15: 300 | H15: 300 | L15: =SUM(E15:K15)-D15 -> 0
A16: 14 | B16: CALVINS OUMA -GRP 16 | C16: 262382 | D16: 10000 | H16: 10000 | L16: =SUM(E16:K16)-D16 -> 0
A17: 15 | B17: GRACE WANGARE | C17: 262383 | D17: 50 | I17: 50 | L17: =SUM(E17:K17)-D17 -> 0
A18: 16 | B18: ERIC NYAMAMBA | C18: 262384 | D18: 10500 | E18: 10500 | L18: =SUM(E18:K18)-D18 -> 0
A19: 17 | B19: ELIAZAR ONGARA | C19: 262385 | D19: 500 | E19: 500 | L19: =SUM(E19:K19)-D19 -> 0
A20: 18 | B20: WINNY-GRP 34 | C20: 262386 | D20: 100 | H20: 100 | L20: =SUM(E20:K20)-D20 -> 0
A21: 19 | B21: ADVENTURERS GROUP | C21: 262387 | D21: 2060 | H21: 2060 | L21: =SUM(E21:K21)-D21 -> 0
A22: 20 | B22: SUSAN OMETE | C22: 262388 | D22: 200 | F22: 200 | L22: =SUM(E22:K22)-D22 -> 0
A23: 21 | B23: EDWIN BOGE -GRP 24 | C23: 262389 | D23: 3250 | H23: 3250 | L23: =SUM(E23:K23)-D23 -> 0
A24: 22 | B24: CECILIA WANGUI | C24: 262390 | D24: 200 | E24: 200 | L24: =SUM(E24:K24)-D24 -> 0
A25: 23 | B25: ROBINSON NYARIBO'S FAMILY | C25: 262391 | D25: 23000 | E25: 22000 | I25: 1000 | L25: =SUM(E25:K25)-D25 -> 0
A26: 24 | B26: OMOSA'S FAMILY | C26: 262392 | D26: 3000 | F26: 2000 | J26: 1000 | L26: =SUM(E26:K26)-D26 -> 0
A27: 25 | B27: MOSETI'S FAMILY | C27: 262393 | D27: 34100 | E27: 34100 | L27: =SUM(E27:K27)-D27 -> 0
A28: 26 | B28: HILDERGAUD KAMANDA | C28: 262394 | D28: 700 | I28: 500 | J28: 200 | L28: =SUM(E28:K28)-D28 -> 0
A29: 27 | B29: ELIAZAR ATULA | C29: 262395 | D29: 150 | E29: 150 | L29: =SUM(E29:K29)-D29 -> 0
A30: 28 | B30: CLEOPAS OMETE | C30: 262396 | D30: 1000 | E30: 1000 | L30: =SUM(E30:K30)-D30 -> 0
A31: 29 | B31: CLIFFORD SIOCHA | C31: 262397 | D31: 500 | I31: 500 | L31: =SUM(E31:K31)-D31 -> 0
A32: 30 | B32: CYNTHIA HUDZON | C32: 262398 | D32: 50 | E32: 50 | L32: =SUM(E32:K32)-D32 -> 0
A33: 31 | B33: DAVIS MIRONGA | C33: 262399 | D33: 1350 | E33: 1350 | L33: =SUM(E33:K33)-D33 -> 0
A34: 32 | B34: DETE OCHIENG | C34: 262400 | D34: 150 | E34: 150 | L34: =SUM(E34:K34)-D34 -> 0
A35: 33 | B35: BOCHABERI OMBORI | C35: 322108 | D35: 200 | H35: 200 | L35: =SUM(E35:K35)-D35 -> 0
A36: 34 | B36: IRENE VARSITY -GRP 11 | C36: 322109 | D36: 200 | H36: 200 | L36: =SUM(E36:K36)-D36 -> 0
A37: 35 | B37: EDWARD ONYANGO-GRP 2 | C37: 322110 | D37: 200 | H37: 200 | L37: =SUM(E37:K37)-D37 -> 0
A38: 36 | B38: PURITY MBATHA -GRP 26 | C38: 322111 | D38: 500 | H38: 500 | L38: =SUM(E38:K38)-D38 -> 0
A39: 37 | B39: GRP 40 | C39: 322112 | D39: 845 | H39: 845 | L39: =SUM(E39:K39)-D39 -> 0
A40: 38 | B40: ESTHER SIOCHA'S FAMILY | C40: 322113 | D40: 6000 | E40: 5000 | H40: 1000 | L40: =SUM(E40:K40)-D40 -> 0
...

Sheet Sheet2
G8: KAMAKIS CRUSADE
G9: DATE | H9: AMOUNT
G10: 45402 | H10: 61750
G11: 45395 | H11: 44350
G12: 45388 | H12: 34600
G13: TOTAL COLLECTION | H13: =SUM(H10:H12) -> 140700
G14: EXPENSES (20/04/2024) | H14: 73000
G16: BALANCE | H16: =H13-H14 -> 67700

Sheet 25TH-EXPENSES
C2: LOCAL CHURCH -EXPENSES
C3: DESCRIPTION | D3: DATE | E3: AMOUNT
C4: 6KG Gas Refill | D4: 45010 | E4: 1500
C5: Holy Communion consumables | D5: 45010 | E5: 4500
C21: TOTALS | E21: =SUM(E4:E20) -> 6000
